{
    "registryname":"biologyreactionchamber",
    "localizedname":"生物反应室",
    "requires-blueprint":true,
    "color":"0000000",
    "parts": [
        {
            "x": 0,
            "y": 0,
            "z": 0,
            "elements": [
                "modularmachinery:blockcontroller@2"
            ]
        },
        {
            "x": -1,
            "y": 0,
            "z": 0,
            "elements": [
                "modularmachinery:blockfluidoutputhatch"
            ]
        },
        {
            "x": 2,
            "y": 4,
            "z": 2,
            "elements": [
                "multi_addon:sheng_wu_fan_ying_shi_wai_ke@0"
            ]
        },
        {
            "x": 1,
            "y": 2,
            "z": 1,
            "elements": [
                "techreborn:fusion_coil@0"
            ]
        },
        {
            "x": -2,
            "y": 0,
            "z": 0,
            "elements": [
                "modularmachinery:blockoutputbus"
            ]
        },
        {
            "x": 2,
            "y": 2,
            "z": 1,
            "elements": [
                "multi_addon:qiang_hua_bo_li@0"
            ]
        },
        {
            "x": 1,
            "y": 0,
            "z": 0,
            "elements": [
                "modularmachinery:blockfluidinputhatch"
            ]
        },
        {
            "x": 2,
            "y": 0,
            "z": 0,
            "elements": [
                "modularmachinery:blockinputbus"
            ]
        },
        {
            "x": -2,
            "y": 0,
            "z": 4,
            "elements": [
                "multi_addon:sheng_wu_fan_ying_shi_wai_ke@0"
            ]
        },
        {
            "x": -1,
            "y": 0,
            "z": 4,
            "elements": [
                "multi_addon:sheng_wu_fan_ying_shi_wai_ke@0"
            ]
        },
        {
            "x": 0,
            "y": 0,
            "z": 4,
            "elements": [
                "modularmachinery:blockenergyinputhatch"
            ]
        },
        {
            "x": 1,
            "y": 0,
            "z": 4,
            "elements": [
                "multi_addon:sheng_wu_fan_ying_shi_wai_ke@0"
            ]
        },
        {
            "x": 2,
            "y": 0,
            "z": 4,
            "elements": [
                "multi_addon:sheng_wu_fan_ying_shi_wai_ke@0"
            ]
        },
        {
            "x": -2,
            "y": 3,
            "z": 1,
            "elements": [
                "multi_addon:qiang_hua_bo_li@0"
            ]
        },
        {
            "x": -2,
            "y": 1,
            "z": 0,
            "elements": [
                "multi_addon:sheng_wu_fan_ying_shi_wai_ke@0"
            ]
        },
        {
            "x": -1,
            "y": 1,
            "z": 0,
            "elements": [
                "multi_addon:qiang_hua_bo_li@0"
            ]
        },
        {
            "x": 0,
            "y": 1,
            "z": 0,
            "elements": [
                "multi_addon:qiang_hua_bo_li@0"
            ]
        },
        {
            "x": 2,
            "y": 3,
            "z": 1,
            "elements": [
                "multi_addon:qiang_hua_bo_li@0"
            ]
        },
        {
            "x": 1,
            "y": 1,
            "z": 0,
            "elements": [
                "multi_addon:qiang_hua_bo_li@0"
            ]
        },
        {
            "x": -2,
            "y": 1,
            "z": 4,
            "elements": [
                "multi_addon:sheng_wu_fan_ying_shi_wai_ke@0"
            ]
        },
        {
            "x": 2,
            "y": 1,
            "z": 0,
            "elements": [
                "multi_addon:sheng_wu_fan_ying_shi_wai_ke@0"
            ]
        },
        {
            "x": -1,
            "y": 1,
            "z": 4,
            "elements": [
                "multi_addon:qiang_hua_bo_li@0"
            ]
        },
        {
            "x": 0,
            "y": 1,
            "z": 4,
            "elements": [
                "multi_addon:qiang_hua_bo_li@0"
            ]
        },
        {
            "x": 1,
            "y": 1,
            "z": 4,
            "elements": [
                "multi_addon:qiang_hua_bo_li@0"
            ]
        },
        {
            "x": 2,
            "y": 1,
            "z": 4,
            "elements": [
                "multi_addon:sheng_wu_fan_ying_shi_wai_ke@0"
            ]
        },
        {
            "x": -2,
            "y": 4,
            "z": 1,
            "elements": [
                "multi_addon:sheng_wu_fan_ying_shi_wai_ke@0"
            ]
        },
        {
            "x": -2,
            "y": 2,
            "z": 0,
            "elements": [
                "multi_addon:sheng_wu_fan_ying_shi_wai_ke@0"
            ]
        },
        {
            "x": -1,
            "y": 4,
            "z": 1,
            "elements": [
                "multi_addon:sheng_wu_fan_ying_shi_wai_ke@0"
            ]
        },
        {
            "x": 0,
            "y": 4,
            "z": 1,
            "elements": [
                "multi_addon:sheng_wu_fan_ying_shi_wai_ke@0"
            ]
        },
        {
            "x": -1,
            "y": 2,
            "z": 0,
            "elements": [
                "multi_addon:qiang_hua_bo_li@0"
            ]
        },
        {
            "x": 1,
            "y": 4,
            "z": 1,
            "elements": [
                "multi_addon:sheng_wu_fan_ying_shi_wai_ke@0"
            ]
        },
        {
            "x": 0,
            "y": 2,
            "z": 0,
            "elements": [
                "multi_addon:qiang_hua_bo_li@0"
            ]
        },
        {
            "x": 2,
            "y": 4,
            "z": 1,
            "elements": [
                "multi_addon:sheng_wu_fan_ying_shi_wai_ke@0"
            ]
        },
        {
            "x": 1,
            "y": 2,
            "z": 0,
            "elements": [
                "multi_addon:qiang_hua_bo_li@0"
            ]
        },
        {
            "x": -2,
            "y": 2,
            "z": 4,
            "elements": [
                "multi_addon:sheng_wu_fan_ying_shi_wai_ke@0"
            ]
        },
        {
            "x": 2,
            "y": 2,
            "z": 0,
            "elements": [
                "multi_addon:sheng_wu_fan_ying_shi_wai_ke@0"
            ]
        },
        {
            "x": -2,
            "y": 0,
            "z": 3,
            "elements": [
                "multi_addon:sheng_wu_fan_ying_shi_wai_ke@0"
            ]
        },
        {
            "x": -1,
            "y": 2,
            "z": 4,
            "elements": [
                "multi_addon:qiang_hua_bo_li@0"
            ]
        },
        {
            "x": 0,
            "y": 2,
            "z": 4,
            "elements": [
                "multi_addon:qiang_hua_bo_li@0"
            ]
        },
        {
            "x": -1,
            "y": 0,
            "z": 3,
            "elements": [
                "multi_addon:sheng_wu_fan_ying_shi_wai_ke@0"
            ]
        },
        {
            "x": 0,
            "y": 0,
            "z": 3,
            "elements": [
                "multi_addon:sheng_wu_fan_ying_shi_wai_ke@0"
            ]
        },
        {
            "x": 1,
            "y": 2,
            "z": 4,
            "elements": [
                "multi_addon:qiang_hua_bo_li@0"
            ]
        },
        {
            "x": 2,
            "y": 2,
            "z": 4,
            "elements": [
                "multi_addon:sheng_wu_fan_ying_shi_wai_ke@0"
            ]
        },
        {
            "x": 1,
            "y": 0,
            "z": 3,
            "elements": [
                "multi_addon:sheng_wu_fan_ying_shi_wai_ke@0"
            ]
        },
        {
            "x": 2,
            "y": 0,
            "z": 3,
            "elements": [
                "multi_addon:sheng_wu_fan_ying_shi_wai_ke@0"
            ]
        },
        {
            "x": -2,
            "y": 3,
            "z": 0,
            "elements": [
                "multi_addon:sheng_wu_fan_ying_shi_wai_ke@0"
            ]
        },
        {
            "x": -1,
            "y": 3,
            "z": 0,
            "elements": [
                "multi_addon:qiang_hua_bo_li@0"
            ]
        },
        {
            "x": 0,
            "y": 3,
            "z": 0,
            "elements": [
                "multi_addon:qiang_hua_bo_li@0"
            ]
        },
        {
            "x": 1,
            "y": 3,
            "z": 0,
            "elements": [
                "multi_addon:qiang_hua_bo_li@0"
            ]
        },
        {
            "x": -2,
            "y": 3,
            "z": 4,
            "elements": [
                "multi_addon:sheng_wu_fan_ying_shi_wai_ke@0"
            ]
        },
        {
            "x": 2,
            "y": 3,
            "z": 0,
            "elements": [
                "multi_addon:sheng_wu_fan_ying_shi_wai_ke@0"
            ]
        },
        {
            "x": -2,
            "y": 1,
            "z": 3,
            "elements": [
                "multi_addon:qiang_hua_bo_li@0"
            ]
        },
        {
            "x": -1,
            "y": 3,
            "z": 4,
            "elements": [
                "multi_addon:qiang_hua_bo_li@0"
            ]
        },
        {
            "x": 0,
            "y": 3,
            "z": 4,
            "elements": [
                "multi_addon:qiang_hua_bo_li@0"
            ]
        },
        {
            "x": 1,
            "y": 3,
            "z": 4,
            "elements": [
                "multi_addon:qiang_hua_bo_li@0"
            ]
        },
        {
            "x": 2,
            "y": 3,
            "z": 4,
            "elements": [
                "multi_addon:sheng_wu_fan_ying_shi_wai_ke@0"
            ]
        },
        {
            "x": 2,
            "y": 1,
            "z": 3,
            "elements": [
                "multi_addon:qiang_hua_bo_li@0"
            ]
        },
        {
            "x": -2,
            "y": 4,
            "z": 0,
            "elements": [
                "multi_addon:sheng_wu_fan_ying_shi_wai_ke@0"
            ]
        },
        {
            "x": -1,
            "y": 4,
            "z": 0,
            "elements": [
                "multi_addon:sheng_wu_fan_ying_shi_wai_ke@0"
            ]
        },
        {
            "x": 0,
            "y": 4,
            "z": 0,
            "elements": [
                "multi_addon:sheng_wu_fan_ying_shi_wai_ke@0"
            ]
        },
        {
            "x": 1,
            "y": 4,
            "z": 0,
            "elements": [
                "multi_addon:sheng_wu_fan_ying_shi_wai_ke@0"
            ]
        },
        {
            "x": -2,
            "y": 4,
            "z": 4,
            "elements": [
                "multi_addon:sheng_wu_fan_ying_shi_wai_ke@0"
            ]
        },
        {
            "x": 2,
            "y": 4,
            "z": 0,
            "elements": [
                "multi_addon:sheng_wu_fan_ying_shi_wai_ke@0"
            ]
        },
        {
            "x": -2,
            "y": 2,
            "z": 3,
            "elements": [
                "multi_addon:qiang_hua_bo_li@0"
            ]
        },
        {
            "x": -1,
            "y": 4,
            "z": 4,
            "elements": [
                "multi_addon:sheng_wu_fan_ying_shi_wai_ke@0"
            ]
        },
        {
            "x": 0,
            "y": 4,
            "z": 4,
            "elements": [
                "multi_addon:sheng_wu_fan_ying_shi_wai_ke@0"
            ]
        },
        {
            "x": -2,
            "y": 0,
            "z": 2,
            "elements": [
                "multi_addon:sheng_wu_fan_ying_shi_wai_ke@0"
            ]
        },
        {
            "x": -1,
            "y": 2,
            "z": 3,
            "elements": [
                "techreborn:fusion_coil@0"
            ]
        },
        {
            "x": 1,
            "y": 4,
            "z": 4,
            "elements": [
                "multi_addon:sheng_wu_fan_ying_shi_wai_ke@0"
            ]
        },
        {
            "x": 0,
            "y": 2,
            "z": 3,
            "elements": [
                "techreborn:fusion_coil@0"
            ]
        },
        {
            "x": -1,
            "y": 0,
            "z": 2,
            "elements": [
                "multi_addon:sheng_wu_fan_ying_shi_wai_ke@0"
            ]
        },
        {
            "x": 0,
            "y": 0,
            "z": 2,
            "elements": [
                "multi_addon:sheng_wu_fan_ying_shi_wai_ke@0"
            ]
        },
        {
            "x": 2,
            "y": 4,
            "z": 4,
            "elements": [
                "multi_addon:sheng_wu_fan_ying_shi_wai_ke@0"
            ]
        },
        {
            "x": 1,
            "y": 2,
            "z": 3,
            "elements": [
                "techreborn:fusion_coil@0"
            ]
        },
        {
            "x": 2,
            "y": 2,
            "z": 3,
            "elements": [
                "multi_addon:qiang_hua_bo_li@0"
            ]
        },
        {
            "x": 1,
            "y": 0,
            "z": 2,
            "elements": [
                "multi_addon:sheng_wu_fan_ying_shi_wai_ke@0"
            ]
        },
        {
            "x": 2,
            "y": 0,
            "z": 2,
            "elements": [
                "multi_addon:sheng_wu_fan_ying_shi_wai_ke@0"
            ]
        },
        {
            "x": -2,
            "y": 3,
            "z": 3,
            "elements": [
                "multi_addon:qiang_hua_bo_li@0"
            ]
        },
        {
            "x": -2,
            "y": 1,
            "z": 2,
            "elements": [
                "multi_addon:qiang_hua_bo_li@0"
            ]
        },
        {
            "x": 0,
            "y": 1,
            "z": 2,
            "elements": [
                "libvulpes:advstructuremachine@0"
            ]
        },
        {
            "x": 2,
            "y": 3,
            "z": 3,
            "elements": [
                "multi_addon:qiang_hua_bo_li@0"
            ]
        },
        {
            "x": 2,
            "y": 1,
            "z": 2,
            "elements": [
                "multi_addon:qiang_hua_bo_li@0"
            ]
        },
        {
            "x": -2,
            "y": 4,
            "z": 3,
            "elements": [
                "multi_addon:sheng_wu_fan_ying_shi_wai_ke@0"
            ]
        },
        {
            "x": -2,
            "y": 2,
            "z": 2,
            "elements": [
                "multi_addon:qiang_hua_bo_li@0"
            ]
        },
        {
            "x": -1,
            "y": 4,
            "z": 3,
            "elements": [
                "multi_addon:sheng_wu_fan_ying_shi_wai_ke@0"
            ]
        },
        {
            "x": 0,
            "y": 4,
            "z": 3,
            "elements": [
                "multi_addon:sheng_wu_fan_ying_shi_wai_ke@0"
            ]
        },
        {
            "x": -2,
            "y": 0,
            "z": 1,
            "elements": [
                "multi_addon:sheng_wu_fan_ying_shi_wai_ke@0"
            ]
        },
        {
            "x": -1,
            "y": 2,
            "z": 2,
            "elements": [
                "techreborn:fusion_coil@0"
            ]
        },
        {
            "x": 1,
            "y": 4,
            "z": 3,
            "elements": [
                "multi_addon:sheng_wu_fan_ying_shi_wai_ke@0"
            ]
        },
        {
            "x": 0,
            "y": 2,
            "z": 2,
            "elements": [
                "draconicevolution:fusion_crafting_core@0"
            ]
        },
        {
            "x": -1,
            "y": 0,
            "z": 1,
            "elements": [
                "multi_addon:sheng_wu_fan_ying_shi_wai_ke@0"
            ]
        },
        {
            "x": 0,
            "y": 0,
            "z": 1,
            "elements": [
                "multi_addon:sheng_wu_fan_ying_shi_wai_ke@0"
            ]
        },
        {
            "x": 2,
            "y": 4,
            "z": 3,
            "elements": [
                "multi_addon:sheng_wu_fan_ying_shi_wai_ke@0"
            ]
        },
        {
            "x": 1,
            "y": 2,
            "z": 2,
            "elements": [
                "techreborn:fusion_coil@0"
            ]
        },
        {
            "x": 2,
            "y": 2,
            "z": 2,
            "elements": [
                "multi_addon:qiang_hua_bo_li@0"
            ]
        },
        {
            "x": 1,
            "y": 0,
            "z": 1,
            "elements": [
                "multi_addon:sheng_wu_fan_ying_shi_wai_ke@0"
            ]
        },
        {
            "x": 2,
            "y": 0,
            "z": 1,
            "elements": [
                "multi_addon:sheng_wu_fan_ying_shi_wai_ke@0"
            ]
        },
        {
            "x": -2,
            "y": 3,
            "z": 2,
            "elements": [
                "multi_addon:qiang_hua_bo_li@0"
            ]
        },
        {
            "x": -2,
            "y": 1,
            "z": 1,
            "elements": [
                "multi_addon:qiang_hua_bo_li@0"
            ]
        },
        {
            "x": 0,
            "y": 3,
            "z": 2,
            "elements": [
                "libvulpes:advstructuremachine@0"
            ]
        },
        {
            "x": 2,
            "y": 3,
            "z": 2,
            "elements": [
                "multi_addon:qiang_hua_bo_li@0"
            ]
        },
        {
            "x": 2,
            "y": 1,
            "z": 1,
            "elements": [
                "multi_addon:qiang_hua_bo_li@0"
            ]
        },
        {
            "x": -2,
            "y": 4,
            "z": 2,
            "elements": [
                "multi_addon:sheng_wu_fan_ying_shi_wai_ke@0"
            ]
        },
        {
            "x": -2,
            "y": 2,
            "z": 1,
            "elements": [
                "multi_addon:qiang_hua_bo_li@0"
            ]
        },
        {
            "x": -1,
            "y": 4,
            "z": 2,
            "elements": [
                "multi_addon:sheng_wu_fan_ying_shi_wai_ke@0"
            ]
        },
        {
            "x": 0,
            "y": 4,
            "z": 2,
            "elements": [
                "multi_addon:sheng_wu_fan_ying_shi_wai_ke@0"
            ]
        },
        {
            "x": -1,
            "y": 2,
            "z": 1,
            "elements": [
                "techreborn:fusion_coil@0"
            ]
        },
        {
            "x": 1,
            "y": 4,
            "z": 2,
            "elements": [
                "multi_addon:sheng_wu_fan_ying_shi_wai_ke@0"
            ]
        },
        {
            "x": 0,
            "y": 2,
            "z": 1,
            "elements": [
                "techreborn:fusion_coil@0"
            ]
        }
    ]}