{
    "registryname":"biologylaboratory",
    "localizedname":"生物实验室",
    "requires-blueprint":true,
    "color":"00E3C4",
    "parts": [
        {
            "x": -1,
            "y": 0,
            "z": 0,
            "elements": [
                "actuallyadditions:block_greenhouse_glass@0"
            ]
        },
        {
            "x": 0,
            "y": 0,
            "z": 0,
            "elements": [
                "modularmachinery:blockcontroller@2"
            ]
        },
        {
            "x": 1,
            "y": 2,
            "z": 1,
            "elements": [
                "botania:cellblock@0"
            ]
        },
        {
            "x": -2,
            "y": 0,
            "z": 0,
            "elements": [
                "actuallyadditions:block_greenhouse_glass@0"
            ]
        },
        {
            "x": 1,
            "y": 0,
            "z": 0,
            "elements": [
                "actuallyadditions:block_greenhouse_glass@0"
            ]
        },
        {
            "x": 2,
            "y": 2,
            "z": 1,
                       "elements": [
                "botania:cellblock@0"
            ]
        },
        {
            "x": -3,
            "y": 0,
            "z": 0,
            "elements": [
                "actuallyadditions:block_greenhouse_glass@0"
            ]
        },
        {
            "x": 2,
            "y": 0,
            "z": 0,
            "elements": [
                "actuallyadditions:block_greenhouse_glass@0"
            ]
        },
        {
            "x": 3,
            "y": 2,
            "z": 1,
                       "elements": [
                "botania:cellblock@0"
            ]
        },
        {
            "x": -4,
            "y": 0,
            "z": 0,
            "elements": [
                "libvulpes:structuremachine@0"
            ]
        },
        {
            "x": 3,
            "y": 0,
            "z": 0,
            "elements": [
                "actuallyadditions:block_greenhouse_glass@0"
            ]
        },
        {
            "x": 4,
            "y": 2,
            "z": 1,
            "elements": [
                "actuallyadditions:block_greenhouse_glass@0"
            ]
        },
        {
            "x": 4,
            "y": 0,
            "z": 0,
            "elements": [
                "libvulpes:structuremachine@0"
            ]
        },
        {
            "x": -4,
            "y": -2,
            "z": 7,
            "elements": [
                "libvulpes:structuremachine@0"
            ]
        },
        {
            "x": -3,
            "y": -2,
            "z": 7,
            "elements": [
                "libvulpes:structuremachine@0"
            ]
        },
        {
            "x": -2,
            "y": -2,
            "z": 7,
            "elements": [
                "libvulpes:structuremachine@0"
            ]
        },
        {
            "x": -1,
            "y": -2,
            "z": 7,
            "elements": [
                "libvulpes:structuremachine@0"
            ]
        },
        {
            "x": 0,
            "y": -2,
            "z": 7,
            "elements": [
                "libvulpes:structuremachine@0"
            ]
        },
        {
            "x": 1,
            "y": -2,
            "z": 7,
            "elements": [
                "libvulpes:structuremachine@0"
            ]
        },
        {
            "x": 2,
            "y": -2,
            "z": 7,
            "elements": [
                "libvulpes:structuremachine@0"
            ]
        },
        {
            "x": 3,
            "y": -2,
            "z": 7,
            "elements": [
                "libvulpes:structuremachine@0"
            ]
        },
        {
            "x": 4,
            "y": -2,
            "z": 7,
            "elements": [
                "libvulpes:structuremachine@0"
            ]
        },
        {
            "x": 4,
            "y": -1,
            "z": 0,
            "elements": [
                "gugu-utils:aurainputhatch@0"
            ]
        },
        {
            "x": -4,
            "y": 3,
            "z": 1,
            "elements": [
                "techreborn:fusion_coil@0"
            ]
        },
        {
            "x": 3,
            "y": -1,
            "z": 0,
            "elements": [
                "avaritia:block_resource@2"
            ]
        },
        {
            "x": -4,
            "y": 1,
            "z": 0,
            "elements": [
                "libvulpes:structuremachine@0"
            ]
        },
        {
            "x": -3,
            "y": 3,
            "z": 1,

            "elements": [
                "modularmachinery:blockcasing@4"
            ]
        },
        {
            "x": 2,
            "y": -1,
            "z": 0,
            "elements": [
                "modularmachinery:blockfluidinputhatch"
            ]
        },
        {
            "x": -3,
            "y": 1,
            "z": 0,
            "elements": [
                "actuallyadditions:block_greenhouse_glass@0"
            ]
        },
        {
            "x": -2,
            "y": 3,
            "z": 1,

            "elements": [
                "modularmachinery:blockcasing@4"
            ]
        },
        {
            "x": 1,
            "y": -1,
            "z": 0,
            "elements": [
                "avaritia:block_resource@2"
            ]
        },
        {
            "x": -2,
            "y": 1,
            "z": 0,
            "elements": [
                "actuallyadditions:block_greenhouse_glass@0"
            ]
        },
        {
            "x": -1,
            "y": 3,
            "z": 1,

            "elements": [
                "modularmachinery:blockcasing@4"
            ]
        },
        {
            "x": 0,
            "y": -1,
            "z": 0,
            "elements": [
                "avaritia:block_resource@2"
            ]
        },
        {
            "x": -1,
            "y": 1,
            "z": 0,
            "elements": [
                "actuallyadditions:block_greenhouse_glass@0"
            ]
        },
        {
            "x": 0,
            "y": 3,
            "z": 1,

            "elements": [
                "modularmachinery:blockcasing@4"
            ]
        },
        {
            "x": -1,
            "y": -1,
            "z": 0,
            "elements": [
                "avaritia:block_resource@2"
            ]
        },
        {
            "x": 0,
            "y": 1,
            "z": 0,
            "elements": [
                "actuallyadditions:block_greenhouse_glass@0"
            ]
        },
        {
            "x": 1,
            "y": 3,
            "z": 1,

            "elements": [
                "modularmachinery:blockcasing@4"
            ]
        },
        {
            "x": -2,
            "y": -1,
            "z": 0,
            "elements": [
                "modularmachinery:blockfluidoutputhatch"
            ]
        },
        {
            "x": 1,
            "y": 1,
            "z": 0,
            "elements": [
                "actuallyadditions:block_greenhouse_glass@0"
            ]
        },
        {
            "x": 2,
            "y": 3,
            "z": 1,

            "elements": [
                "modularmachinery:blockcasing@4"
            ]
        },
        {
            "x": -3,
            "y": -1,
            "z": 0,
            "elements": [
                "avaritia:block_resource@2"
            ]
        },
        {
            "x": 2,
            "y": 1,
            "z": 0,
            "elements": [
                "actuallyadditions:block_greenhouse_glass@0"
            ]
        },
        {
            "x": 3,
            "y": 3,
            "z": 1,

            "elements": [
                "modularmachinery:blockcasing@4"
            ]
        },
        {
            "x": -4,
            "y": -1,
            "z": 0,
            "elements": [
                "modularmachinery:blockfluidoutputhatch"
            ]
        },
        {
            "x": 3,
            "y": 1,
            "z": 0,
            "elements": [
                "actuallyadditions:block_greenhouse_glass@0"
            ]
        },
        {
            "x": 4,
            "y": 3,
            "z": 1,
            "elements": [
                "techreborn:fusion_coil@0"
            ]
        },
        {
            "x": 4,
            "y": 1,
            "z": 0,
            "elements": [
                "libvulpes:structuremachine@0"
            ]
        },
        {
            "x": -4,
            "y": -1,
            "z": 7,
            "elements": [
                "libvulpes:structuremachine@0"
            ]
        },
        {
            "x": -3,
            "y": -1,
            "z": 7,
            "elements": [
                "techreborn:fusion_coil@0"
            ]
        },
        {
            "x": -2,
            "y": -1,
            "z": 7,
            "elements": [
                "techreborn:fusion_coil@0"
            ]
        },
        {
            "x": -1,
            "y": -1,
            "z": 7,
            "elements": [
                "techreborn:fusion_coil@0"
            ]
        },
        {
            "x": 0,
            "y": -1,
            "z": 7,
            "elements": [
                "techreborn:fusion_coil@0"
            ]
        },
        {
            "x": 1,
            "y": -1,
            "z": 7,
            "elements": [
                "techreborn:fusion_coil@0"
            ]
        },
        {
            "x": 2,
            "y": -1,
            "z": 7,
            "elements": [
                "techreborn:fusion_coil@0"
            ]
        },
        {
            "x": 3,
            "y": -1,
            "z": 7,
            "elements": [
                "techreborn:fusion_coil@0"
            ]
        },
        {
            "x": 4,
            "y": -1,
            "z": 7,
            "elements": [
                "libvulpes:structuremachine@0"
            ]
        },
        {
            "x": 4,
            "y": -2,
            "z": 0,
            "elements": [
                "libvulpes:structuremachine@0"
            ]
        },
        {
            "x": 3,
            "y": -2,
            "z": 0,
            "elements": [
                "modularmachinery:blockenergyinputhatch"
            ]
        },
        {
            "x": -4,
            "y": 2,
            "z": 0,
            "elements": [
                "libvulpes:structuremachine@0"
            ]
        },
        {
            "x": 2,
            "y": -2,
            "z": 0,
            "elements": [
                "libvulpes:structuremachine@0"
            ]
        },
        {
            "x": -3,
            "y": 2,
            "z": 0,
            "elements": [
                "actuallyadditions:block_greenhouse_glass@0"
            ]
        },
        {
            "x": 1,
            "y": -2,
            "z": 0,
            "elements": [
                "libvulpes:structuremachine@0"
            ]
        },
        {
            "x": -2,
            "y": 2,
            "z": 0,
            "elements": [
                "actuallyadditions:block_greenhouse_glass@0"
            ]
        },
        {
            "x": 0,
            "y": -2,
            "z": 0,
            "elements": [
                "libvulpes:structuremachine@0"
            ]
        },
        {
            "x": -1,
            "y": 2,
            "z": 0,
            "elements": [
                "actuallyadditions:block_greenhouse_glass@0"
            ]
        },
        {
            "x": -1,
            "y": -2,
            "z": 0,
            "elements": [
                "libvulpes:structuremachine@0"
            ]
        },
        {
            "x": 0,
            "y": 2,
            "z": 0,
            "elements": [
                "actuallyadditions:block_greenhouse_glass@0"
            ]
        },
        {
            "x": -2,
            "y": -2,
            "z": 0,
            "elements": [
                "libvulpes:structuremachine@0"
            ]
        },
        {
            "x": 1,
            "y": 2,
            "z": 0,
            "elements": [
                "actuallyadditions:block_greenhouse_glass@0"
            ]
        },
        {
            "x": -3,
            "y": -2,
            "z": 0,
            "elements": [
                "modularmachinery:blockoutputbus"
            ]
        },
        {
            "x": 2,
            "y": 2,
            "z": 0,
            "elements": [
                "actuallyadditions:block_greenhouse_glass@0"
            ]
        },
        {
            "x": -4,
            "y": -2,
            "z": 0,
            "elements": [
                "libvulpes:structuremachine@0"
            ]
        },
        {
            "x": 3,
            "y": 2,
            "z": 0,
            "elements": [
                "actuallyadditions:block_greenhouse_glass@0"
            ]
        },
        {
            "x": 4,
            "y": 2,
            "z": 0,
            "elements": [
                "libvulpes:structuremachine@0"
            ]
        },
        {
            "x": -4,
            "y": 0,
            "z": 7,
            "elements": [
                "libvulpes:structuremachine@0"
            ]
        },
        {
            "x": -4,
            "y": -2,
            "z": 6,
            "elements": [
                "libvulpes:structuremachine@0"
            ]
        },
        {
            "x": -3,
            "y": 0,
            "z": 7,
            "elements": [
                "actuallyadditions:block_greenhouse_glass@0"
            ]
        },
        {
            "x": -3,
            "y": -2,
            "z": 6,
            "elements": [
                "libvulpes:structuremachine@0"
            ]
        },
        {
            "x": -2,
            "y": 0,
            "z": 7,
            "elements": [
                "actuallyadditions:block_greenhouse_glass@0"
            ]
        },
        {
            "x": -2,
            "y": -2,
            "z": 6,
            "elements": [
                "libvulpes:structuremachine@0"
            ]
        },
        {
            "x": -1,
            "y": 0,
            "z": 7,
            "elements": [
                "actuallyadditions:block_greenhouse_glass@0"
            ]
        },
        {
            "x": -1,
            "y": -2,
            "z": 6,
            "elements": [
                "libvulpes:structuremachine@0"
            ]
        },
        {
            "x": 0,
            "y": 0,
            "z": 7,
            "elements": [
                "actuallyadditions:block_greenhouse_glass@0"
            ]
        },
        {
            "x": 0,
            "y": -2,
            "z": 6,
            "elements": [
                "libvulpes:structuremachine@0"
            ]
        },
        {
            "x": 1,
            "y": 0,
            "z": 7,
            "elements": [
                "actuallyadditions:block_greenhouse_glass@0"
            ]
        },
        {
            "x": 1,
            "y": -2,
            "z": 6,
            "elements": [
                "libvulpes:structuremachine@0"
            ]
        },
        {
            "x": 2,
            "y": 0,
            "z": 7,
            "elements": [
                "actuallyadditions:block_greenhouse_glass@0"
            ]
        },
        {
            "x": 2,
            "y": -2,
            "z": 6,
            "elements": [
                "libvulpes:structuremachine@0"
            ]
        },
        {
            "x": 3,
            "y": 0,
            "z": 7,
            "elements": [
                "actuallyadditions:block_greenhouse_glass@0"
            ]
        },
        {
            "x": 3,
            "y": -2,
            "z": 6,
            "elements": [
                "libvulpes:structuremachine@0"
            ]
        },
        {
            "x": 4,
            "y": 0,
            "z": 7,
            "elements": [
                "libvulpes:structuremachine@0"
            ]
        },
        {
            "x": 4,
            "y": -2,
            "z": 6,
            "elements": [
                "libvulpes:structuremachine@0"
            ]
        },
        {
            "x": -4,
            "y": 3,
            "z": 0,
            "elements": [
                "libvulpes:structuremachine@0"
            ]
        },
        {
            "x": -3,
            "y": 3,
            "z": 0,
            "elements": [
                "techreborn:fusion_coil@0"
            ]
        },
        {
            "x": -2,
            "y": 3,
            "z": 0,
            "elements": [
                "techreborn:fusion_coil@0"
            ]
        },
        {
            "x": -1,
            "y": 3,
            "z": 0,
            "elements": [
                "techreborn:fusion_coil@0"
            ]
        },
        {
            "x": 0,
            "y": 3,
            "z": 0,
            "elements": [
                "techreborn:fusion_coil@0"
            ]
        },
        {
            "x": 1,
            "y": 3,
            "z": 0,
            "elements": [
                "techreborn:fusion_coil@0"
            ]
        },
        {
            "x": 2,
            "y": 3,
            "z": 0,
            "elements": [
                "techreborn:fusion_coil@0"
            ]
        },
        {
            "x": 3,
            "y": 3,
            "z": 0,
            "elements": [
                "techreborn:fusion_coil@0"
            ]
        },
        {
            "x": 4,
            "y": 3,
            "z": 0,
            "elements": [
                "libvulpes:structuremachine@0"
            ]
        },
        {
            "x": -4,
            "y": 1,
            "z": 7,
            "elements": [
                "libvulpes:structuremachine@0"
            ]
        },
        {
            "x": -4,
            "y": -1,
            "z": 6,
            "elements": [
                "techreborn:fusion_coil@0"
            ]
        },
        {
            "x": -3,
            "y": 1,
            "z": 7,
            "elements": [
                "actuallyadditions:block_greenhouse_glass@0"
            ]
        },
        {
            "x": -3,
            "y": -1,
            "z": 6,
            "elements": [
                "mysticalagriculture:ingot_storage@5"
            ]
        },
        {
            "x": -2,
            "y": 1,
            "z": 7,
            "elements": [
                "actuallyadditions:block_greenhouse_glass@0"
            ]
        },
        {
            "x": -2,
            "y": -1,
            "z": 6,
                       "elements": [
                "botania:cellblock@0"
            ]
        },
        {
            "x": -1,
            "y": 1,
            "z": 7,
            "elements": [
                "actuallyadditions:block_greenhouse_glass@0"
            ]
        },
        {
            "x": -1,
            "y": -1,
            "z": 6,
                       "elements": [
                "botania:cellblock@0"
            ]
        },
        {
            "x": 0,
            "y": 1,
            "z": 7,
            "elements": [
                "actuallyadditions:block_greenhouse_glass@0"
            ]
        },
        {
            "x": 0,
            "y": -1,
            "z": 6,
                       "elements": [
                "botania:cellblock@0"
            ]
        },
        {
            "x": 1,
            "y": 1,
            "z": 7,
            "elements": [
                "actuallyadditions:block_greenhouse_glass@0"
            ]
        },
        {
            "x": 1,
            "y": -1,
            "z": 6,
                       "elements": [
                "botania:cellblock@0"
            ]
        },
        {
            "x": 2,
            "y": 1,
            "z": 7,
            "elements": [
                "actuallyadditions:block_greenhouse_glass@0"
            ]
        },
        {
            "x": 2,
            "y": -1,
            "z": 6,
                       "elements": [
                "botania:cellblock@0"
            ]
        },
        {
            "x": 3,
            "y": 1,
            "z": 7,
            "elements": [
                "actuallyadditions:block_greenhouse_glass@0"
            ]
        },
        {
            "x": 3,
            "y": -1,
            "z": 6,
            "elements": [
                "mysticalagriculture:ingot_storage@5"
            ]
        },
        {
            "x": 4,
            "y": 1,
            "z": 7,
            "elements": [
                "libvulpes:structuremachine@0"
            ]
        },
        {
            "x": 4,
            "y": -1,
            "z": 6,
            "elements": [
                "techreborn:fusion_coil@0"
            ]
        },
        {
            "x": -4,
            "y": 2,
            "z": 7,
            "elements": [
                "libvulpes:structuremachine@0"
            ]
        },
        {
            "x": -4,
            "y": 0,
            "z": 6,
            "elements": [
                "actuallyadditions:block_greenhouse_glass@0"
            ]
        },
        {
            "x": -3,
            "y": 2,
            "z": 7,
            "elements": [
                "actuallyadditions:block_greenhouse_glass@0"
            ]
        },
        {
            "x": -4,
            "y": -2,
            "z": 5,
            "elements": [
                "libvulpes:structuremachine@0"
            ]
        },
        {
            "x": -2,
            "y": 2,
            "z": 7,
            "elements": [
                "actuallyadditions:block_greenhouse_glass@0"
            ]
        },
        {
            "x": -3,
            "y": -2,
            "z": 5,
            "elements": [
                "libvulpes:structuremachine@0"
            ]
        },
        {
            "x": -1,
            "y": 2,
            "z": 7,
            "elements": [
                "actuallyadditions:block_greenhouse_glass@0"
            ]
        },
        {
            "x": -2,
            "y": -2,
            "z": 5,
            "elements": [
                "libvulpes:structuremachine@0"
            ]
        },
        {
            "x": 0,
            "y": 2,
            "z": 7,
            "elements": [
                "actuallyadditions:block_greenhouse_glass@0"
            ]
        },
        {
            "x": -1,
            "y": -2,
            "z": 5,
            "elements": [
                "libvulpes:structuremachine@0"
            ]
        },
        {
            "x": 1,
            "y": 2,
            "z": 7,
            "elements": [
                "actuallyadditions:block_greenhouse_glass@0"
            ]
        },
        {
            "x": 0,
            "y": -2,
            "z": 5,
            "elements": [
                "libvulpes:structuremachine@0"
            ]
        },
        {
            "x": 2,
            "y": 2,
            "z": 7,
            "elements": [
                "actuallyadditions:block_greenhouse_glass@0"
            ]
        },
        {
            "x": 1,
            "y": -2,
            "z": 5,
            "elements": [
                "libvulpes:structuremachine@0"
            ]
        },
        {
            "x": 3,
            "y": 2,
            "z": 7,
            "elements": [
                "actuallyadditions:block_greenhouse_glass@0"
            ]
        },
        {
            "x": 2,
            "y": -2,
            "z": 5,
            "elements": [
                "libvulpes:structuremachine@0"
            ]
        },
        {
            "x": 4,
            "y": 2,
            "z": 7,
            "elements": [
                "libvulpes:structuremachine@0"
            ]
        },
        {
            "x": 3,
            "y": -2,
            "z": 5,
            "elements": [
                "libvulpes:structuremachine@0"
            ]
        },
        {
            "x": 4,
            "y": 0,
            "z": 6,
            "elements": [
                "actuallyadditions:block_greenhouse_glass@0"
            ]
        },
        {
            "x": 4,
            "y": -2,
            "z": 5,
            "elements": [
                "libvulpes:structuremachine@0"
            ]
        },
        {
            "x": -4,
            "y": 3,
            "z": 7,
            "elements": [
                "libvulpes:structuremachine@0"
            ]
        },
        {
            "x": -4,
            "y": 1,
            "z": 6,
            "elements": [
                "actuallyadditions:block_greenhouse_glass@0"
            ]
        },
        {
            "x": -3,
            "y": 3,
            "z": 7,
            "elements": [
                "techreborn:fusion_coil@0"
            ]
        },
        {
            "x": -4,
            "y": -1,
            "z": 5,
            "elements": [
                "techreborn:fusion_coil@0"
            ]
        },
        {
            "x": -2,
            "y": 3,
            "z": 7,
            "elements": [
                "techreborn:fusion_coil@0"
            ]
        },
        {
            "x": -3,
            "y": -1,
            "z": 5,
            "elements": [
                "botania:cellblock@0"
            ]
        },
        {
            "x": -1,
            "y": 3,
            "z": 7,
            "elements": [
                "techreborn:fusion_coil@0"
            ]
        },
        {
            "x": -2,
            "y": -1,
            "z": 5,
            "elements": [
                "botania:cellblock@0"
            ]
        },
        {
            "x": 0,
            "y": 3,
            "z": 7,
            "elements": [
                "techreborn:fusion_coil@0"
            ]
        },
        {
            "x": -1,
            "y": -1,
            "z": 5,
             "elements": [
                "botania:cellblock@0"
            ]
        },
        {
            "x": 1,
            "y": 3,
            "z": 7,
            "elements": [
                "techreborn:fusion_coil@0"
            ]
        },
        {
            "x": 0,
            "y": -1,
            "z": 5,
            "elements": [
                "botania:cellblock@0"
            ]
        },
        {
            "x": 2,
            "y": 3,
            "z": 7,
            "elements": [
                "techreborn:fusion_coil@0"
            ]
        },
        {
            "x": 1,
            "y": -1,
            "z": 5,
                       "elements": [
                "botania:cellblock@0"
            ]
        },
        {
            "x": 3,
            "y": 3,
            "z": 7,
            "elements": [
                "techreborn:fusion_coil@0"
            ]
        },
        {
            "x": 2,
            "y": -1,
            "z": 5,
                       "elements": [
                "botania:cellblock@0"
            ]
        },
        {
            "x": 4,
            "y": 3,
            "z": 7,
            "elements": [
                "libvulpes:structuremachine@0"
            ]
        },
        {
            "x": 3,
            "y": -1,
            "z": 5,
                       "elements": [
                "botania:cellblock@0"
            ]
        },
        {
            "x": 4,
            "y": 1,
            "z": 6,
            "elements": [
                "actuallyadditions:block_greenhouse_glass@0"
            ]
        },
        {
            "x": 4,
            "y": -1,
            "z": 5,
            "elements": [
                "techreborn:fusion_coil@0"
            ]
        },
        {
            "x": -4,
            "y": 2,
            "z": 6,
            "elements": [
                "actuallyadditions:block_greenhouse_glass@0"
            ]
        },
        {
            "x": -4,
            "y": 0,
            "z": 5,
            "elements": [
                "actuallyadditions:block_greenhouse_glass@0"
            ]
        },
        {
            "x": -3,
            "y": 2,
            "z": 6,
            "elements": [
                "botania:cellblock@0"
            ]
        },
        {
            "x": -4,
            "y": -2,
            "z": 4,
            "elements": [
                "libvulpes:structuremachine@0"
            ]
        },
        {
            "x": -2,
            "y": 2,
            "z": 6,
                       "elements": [
                "botania:cellblock@0"
            ]
        },
        {
            "x": -3,
            "y": -2,
            "z": 4,
            "elements": [
                "libvulpes:structuremachine@0"
            ]
        },
        {
            "x": -1,
            "y": 2,
            "z": 6,
                       "elements": [
                "botania:cellblock@0"
            ]
        },
        {
            "x": -2,
            "y": -2,
            "z": 4,
            "elements": [
                "libvulpes:structuremachine@0"
            ]
        },
        {
            "x": -1,
            "y": 0,
            "z": 5,
                       "elements": [
                "botania:cellblock@0"
            ]
        },
        {
            "x": 0,
            "y": 2,
            "z": 6,
                       "elements": [
                "botania:cellblock@0"
            ]
        },
        {
            "x": -1,
            "y": -2,
            "z": 4,
            "elements": [
                "libvulpes:structuremachine@0"
            ]
        },
        {
            "x": 0,
            "y": 0,
            "z": 5,
                       "elements": [
                "botania:cellblock@0"
            ]
        },
        {
            "x": 1,
            "y": 2,
            "z": 6,
                       "elements": [
                "botania:cellblock@0"
            ]
        },
        {
            "x": 0,
            "y": -2,
            "z": 4,
            "elements": [
                "libvulpes:structuremachine@0"
            ]
        },
        {
            "x": 1,
            "y": 0,
            "z": 5,
                       "elements": [
                "botania:cellblock@0"
            ]
        },
        {
            "x": 2,
            "y": 2,
            "z": 6,
                       "elements": [
                "botania:cellblock@0"
            ]
        },
        {
            "x": 1,
            "y": -2,
            "z": 4,
            "elements": [
                "libvulpes:structuremachine@0"
            ]
        },
        {
            "x": 3,
            "y": 2,
            "z": 6,
                       "elements": [
                "botania:cellblock@0"
            ]
        },
        {
            "x": 2,
            "y": -2,
            "z": 4,
            "elements": [
                "libvulpes:structuremachine@0"
            ]
        },
        {
            "x": 4,
            "y": 2,
            "z": 6,
            "elements": [
                "actuallyadditions:block_greenhouse_glass@0"
            ]
        },
        {
            "x": 3,
            "y": -2,
            "z": 4,
            "elements": [
                "libvulpes:structuremachine@0"
            ]
        },
        {
            "x": 4,
            "y": 0,
            "z": 5,
            "elements": [
                "actuallyadditions:block_greenhouse_glass@0"
            ]
        },
        {
            "x": 4,
            "y": -2,
            "z": 4,
            "elements": [
                "libvulpes:structuremachine@0"
            ]
        },
        {
            "x": -4,
            "y": 3,
            "z": 6,
            "elements": [
                "techreborn:fusion_coil@0"
            ]
        },
        {
            "x": -4,
            "y": 1,
            "z": 5,
            "elements": [
                "actuallyadditions:block_greenhouse_glass@0"
            ]
        },
        {
            "x": -3,
            "y": 3,
            "z": 6,

            "elements": [
                "modularmachinery:blockcasing@4"
            ]
        },
        {
            "x": -4,
            "y": -1,
            "z": 4,
            "elements": [
                "techreborn:fusion_coil@0"
            ]
        },
        {
            "x": -2,
            "y": 3,
            "z": 6,

            "elements": [
                "modularmachinery:blockcasing@4"
            ]
        },
        {
            "x": -3,
            "y": -1,
            "z": 4,
                       "elements": [
                "botania:cellblock@0"
            ]
        },
        {
            "x": -1,
            "y": 3,
            "z": 6,

            "elements": [
                "modularmachinery:blockcasing@4"
            ]
        },
        {
            "x": -2,
            "y": -1,
            "z": 4,
                       "elements": [
                "botania:cellblock@0"
            ]
        },
        {
            "x": -1,
            "y": 1,
            "z": 5,
                       "elements": [
                "botania:cellblock@0"
            ]
        },
        {
            "x": 0,
            "y": 3,
            "z": 6,

            "elements": [
                "modularmachinery:blockcasing@4"
            ]
        },
        {
            "x": -1,
            "y": -1,
            "z": 4,
                       "elements": [
                "botania:cellblock@0"
            ]
        },
        {
            "x": 0,
            "y": 1,
            "z": 5,
                       "elements": [
                "botania:cellblock@0"
            ]
        },
        {
            "x": 1,
            "y": 3,
            "z": 6,

            "elements": [
                "modularmachinery:blockcasing@4"
            ]
        },
        {
            "x": 0,
            "y": -1,
            "z": 4,
                       "elements": [
                "botania:cellblock@0"
            ]
        },
        {
            "x": 1,
            "y": 1,
            "z": 5,
                       "elements": [
                "botania:cellblock@0"
            ]
        },
        {
            "x": 2,
            "y": 3,
            "z": 6,

            "elements": [
                "modularmachinery:blockcasing@4"
            ]
        },
        {
            "x": 1,
            "y": -1,
            "z": 4,
                       "elements": [
                "botania:cellblock@0"
            ]
        },
        {
            "x": 3,
            "y": 3,
            "z": 6,

            "elements": [
                "modularmachinery:blockcasing@4"
            ]
        },
        {
            "x": 2,
            "y": -1,
            "z": 4,
                       "elements": [
                "botania:cellblock@0"
            ]
        },
        {
            "x": 4,
            "y": 3,
            "z": 6,
            "elements": [
                "techreborn:fusion_coil@0"
            ]
        },
        {
            "x": 3,
            "y": -1,
            "z": 4,
                       "elements": [
                "botania:cellblock@0"
            ]
        },
        {
            "x": 4,
            "y": 1,
            "z": 5,
            "elements": [
                "actuallyadditions:block_greenhouse_glass@0"
            ]
        },
        {
            "x": 4,
            "y": -1,
            "z": 4,
            "elements": [
                "techreborn:fusion_coil@0"
            ]
        },
        {
            "x": -4,
            "y": 2,
            "z": 5,
            "elements": [
                "actuallyadditions:block_greenhouse_glass@0"
            ]
        },
        {
            "x": -4,
            "y": 0,
            "z": 4,
            "elements": [
                "actuallyadditions:block_greenhouse_glass@0"
            ]
        },
        {
            "x": -3,
            "y": 2,
            "z": 5,
                       "elements": [
                "botania:cellblock@0"
            ]
        },
        {
            "x": -4,
            "y": -2,
            "z": 3,
            "elements": [
                "libvulpes:structuremachine@0"
            ]
        },
        {
            "x": -2,
            "y": 2,
            "z": 5,
                       "elements": [
                "botania:cellblock@0"
            ]
        },
        {
            "x": -3,
            "y": -2,
            "z": 3,
            "elements": [
                "libvulpes:structuremachine@0"
            ]
        },
        {
            "x": -1,
            "y": 2,
            "z": 5,
                       "elements": [
                "botania:cellblock@0"
            ]
        },
        {
            "x": -2,
            "y": -2,
            "z": 3,
            "elements": [
                "libvulpes:structuremachine@0"
            ]
        },
        {
            "x": -1,
            "y": 0,
            "z": 4,
                       "elements": [
                "botania:cellblock@0"
            ]
        },
        {
            "x": 0,
            "y": 2,
            "z": 5,
                       "elements": [
                "botania:cellblock@0"
            ]
        },
        {
            "x": -1,
            "y": -2,
            "z": 3,
            "elements": [
                "libvulpes:structuremachine@0"
            ]
        },
        {
            "x": 0,
            "y": 0,
            "z": 4,
            "elements": [
                "bloodarsenal:refined_life_essence@0"
            ]
        },
        {
            "x": 1,
            "y": 2,
            "z": 5,
                       "elements": [
                "botania:cellblock@0"
            ]
        },
        {
            "x": 0,
            "y": -2,
            "z": 3,
            "elements": [
                "libvulpes:structuremachine@0"
            ]
        },
        {
            "x": 1,
            "y": 0,
            "z": 4,
                       "elements": [
                "botania:cellblock@0"
            ]
        },
        {
            "x": 2,
            "y": 2,
            "z": 5,
                       "elements": [
                "botania:cellblock@0"
            ]
        },
        {
            "x": 1,
            "y": -2,
            "z": 3,
            "elements": [
                "libvulpes:structuremachine@0"
            ]
        },
        {
            "x": 3,
            "y": 2,
            "z": 5,
                       "elements": [
                "botania:cellblock@0"
            ]
        },
        {
            "x": 2,
            "y": -2,
            "z": 3,
            "elements": [
                "libvulpes:structuremachine@0"
            ]
        },
        {
            "x": 4,
            "y": 2,
            "z": 5,
            "elements": [
                "actuallyadditions:block_greenhouse_glass@0"
            ]
        },
        {
            "x": 3,
            "y": -2,
            "z": 3,
            "elements": [
                "libvulpes:structuremachine@0"
            ]
        },
        {
            "x": 4,
            "y": 0,
            "z": 4,
            "elements": [
                "actuallyadditions:block_greenhouse_glass@0"
            ]
        },
        {
            "x": 4,
            "y": -2,
            "z": 3,
            "elements": [
                "libvulpes:structuremachine@0"
            ]
        },
        {
            "x": -4,
            "y": 3,
            "z": 5,
            "elements": [
                "techreborn:fusion_coil@0"
            ]
        },
        {
            "x": -4,
            "y": 1,
            "z": 4,
            "elements": [
                "actuallyadditions:block_greenhouse_glass@0"
            ]
        },
        {
            "x": -3,
            "y": 3,
            "z": 5,

            "elements": [
                "modularmachinery:blockcasing@4"
            ]
        },
        {
            "x": -4,
            "y": -1,
            "z": 3,
            "elements": [
                "techreborn:fusion_coil@0"
            ]
        },
        {
            "x": -2,
            "y": 3,
            "z": 5,

            "elements": [
                "modularmachinery:blockcasing@4"
            ]
        },
        {
            "x": -3,
            "y": -1,
            "z": 3,
                       "elements": [
                "botania:cellblock@0"
            ]
        },
        {
            "x": -1,
            "y": 3,
            "z": 5,

            "elements": [
                "modularmachinery:blockcasing@4"
            ]
        },
        {
            "x": -2,
            "y": -1,
            "z": 3,
                       "elements": [
                "botania:cellblock@0"
            ]
        },
        {
            "x": -1,
            "y": 1,
            "z": 4,
                       "elements": [
                "botania:cellblock@0"
            ]
        },
        {
            "x": 0,
            "y": 3,
            "z": 5,

            "elements": [
                "modularmachinery:blockcasing@4"
            ]
        },
        {
            "x": -1,
            "y": -1,
            "z": 3,
                       "elements": [
                "botania:cellblock@0"
            ]
        },
        {
            "x": 0,
            "y": 1,
            "z": 4,
            "elements": [
                "bloodarsenal:refined_life_essence@0"
            ]
        },
        {
            "x": 1,
            "y": 3,
            "z": 5,

            "elements": [
                "modularmachinery:blockcasing@4"
            ]
        },
        {
            "x": 0,
            "y": -1,
            "z": 3,
                       "elements": [
                "botania:cellblock@0"
            ]
        },
        {
            "x": 1,
            "y": 1,
            "z": 4,
                       "elements": [
                "botania:cellblock@0"
            ]
        },
        {
            "x": 2,
            "y": 3,
            "z": 5,

            "elements": [
                "modularmachinery:blockcasing@4"
            ]
        },
        {
            "x": 1,
            "y": -1,
            "z": 3,
                       "elements": [
                "botania:cellblock@0"
            ]
        },
        {
            "x": 3,
            "y": 3,
            "z": 5,

            "elements": [
                "modularmachinery:blockcasing@4"
            ]
        },
        {
            "x": 2,
            "y": -1,
            "z": 3,
                       "elements": [
                "botania:cellblock@0"
            ]
        },
        {
            "x": 4,
            "y": 3,
            "z": 5,
            "elements": [
                "techreborn:fusion_coil@0"
            ]
        },
        {
            "x": 3,
            "y": -1,
            "z": 3,
                       "elements": [
                "botania:cellblock@0"
            ]
        },
        {
            "x": 4,
            "y": 1,
            "z": 4,
            "elements": [
                "actuallyadditions:block_greenhouse_glass@0"
            ]
        },
        {
            "x": 4,
            "y": -1,
            "z": 3,
            "elements": [
                "techreborn:fusion_coil@0"
            ]
        },
        {
            "x": -4,
            "y": 2,
            "z": 4,
            "elements": [
                "actuallyadditions:block_greenhouse_glass@0"
            ]
        },
        {
            "x": -4,
            "y": 0,
            "z": 3,
            "elements": [
                "actuallyadditions:block_greenhouse_glass@0"
            ]
        },
        {
            "x": -3,
            "y": 2,
            "z": 4,
                       "elements": [
                "botania:cellblock@0"
            ]
        },
        {
            "x": -4,
            "y": -2,
            "z": 2,
            "elements": [
                "libvulpes:structuremachine@0"
            ]
        },
        {
            "x": -2,
            "y": 2,
            "z": 4,
                       "elements": [
                "botania:cellblock@0"
            ]
        },
        {
            "x": -3,
            "y": -2,
            "z": 2,
            "elements": [
                "libvulpes:structuremachine@0"
            ]
        },
        {
            "x": -1,
            "y": 2,
            "z": 4,
                       "elements": [
                "botania:cellblock@0"
            ]
        },
        {
            "x": -2,
            "y": -2,
            "z": 2,
            "elements": [
                "libvulpes:structuremachine@0"
            ]
        },
        {
            "x": -1,
            "y": 0,
            "z": 3,
                       "elements": [
                "botania:cellblock@0"
            ]
        },
        {
            "x": 0,
            "y": 2,
            "z": 4,
                       "elements": [
                "botania:cellblock@0"
            ]
        },
        {
            "x": -1,
            "y": -2,
            "z": 2,
            "elements": [
                "libvulpes:structuremachine@0"
            ]
        },
        {
            "x": 0,
            "y": 0,
            "z": 3,
            "elements": [
                "bloodarsenal:refined_life_essence@0"
            ]
        },
        {
            "x": 1,
            "y": 2,
            "z": 4,
                       "elements": [
                "botania:cellblock@0"
            ]
        },
        {
            "x": 0,
            "y": -2,
            "z": 2,
            "elements": [
                "libvulpes:structuremachine@0"
            ]
        },
        {
            "x": 1,
            "y": 0,
            "z": 3,
                       "elements": [
                "botania:cellblock@0"
            ]
        },
        {
            "x": 2,
            "y": 2,
            "z": 4,
                       "elements": [
                "botania:cellblock@0"
            ]
        },
        {
            "x": 1,
            "y": -2,
            "z": 2,
            "elements": [
                "libvulpes:structuremachine@0"
            ]
        },
        {
            "x": 3,
            "y": 2,
            "z": 4,
                       "elements": [
                "botania:cellblock@0"
            ]
        },
        {
            "x": 2,
            "y": -2,
            "z": 2,
            "elements": [
                "libvulpes:structuremachine@0"
            ]
        },
        {
            "x": 4,
            "y": 2,
            "z": 4,
            "elements": [
                "actuallyadditions:block_greenhouse_glass@0"
            ]
        },
        {
            "x": 3,
            "y": -2,
            "z": 2,
            "elements": [
                "libvulpes:structuremachine@0"
            ]
        },
        {
            "x": 4,
            "y": 0,
            "z": 3,
            "elements": [
                "actuallyadditions:block_greenhouse_glass@0"
            ]
        },
        {
            "x": 4,
            "y": -2,
            "z": 2,
            "elements": [
                "libvulpes:structuremachine@0"
            ]
        },
        {
            "x": -4,
            "y": 3,
            "z": 4,
            "elements": [
                "techreborn:fusion_coil@0"
            ]
        },
        {
            "x": -4,
            "y": 1,
            "z": 3,
            "elements": [
                "actuallyadditions:block_greenhouse_glass@0"
            ]
        },
        {
            "x": -3,
            "y": 3,
            "z": 4,

            "elements": [
                "modularmachinery:blockcasing@4"
            ]
        },
        {
            "x": -4,
            "y": -1,
            "z": 2,
            "elements": [
                "techreborn:fusion_coil@0"
            ]
        },
        {
            "x": -2,
            "y": 3,
            "z": 4,

            "elements": [
                "modularmachinery:blockcasing@4"
            ]
        },
        {
            "x": -3,
            "y": -1,
            "z": 2,
                       "elements": [
                "botania:cellblock@0"
            ]
        },
        {
            "x": -1,
            "y": 3,
            "z": 4,

            "elements": [
                "modularmachinery:blockcasing@4"
            ]
        },
        {
            "x": -2,
            "y": -1,
            "z": 2,
                       "elements": [
                "botania:cellblock@0"
            ]
        },
        {
            "x": -1,
            "y": 1,
            "z": 3,
                       "elements": [
                "botania:cellblock@0"
            ]
        },
        {
            "x": 0,
            "y": 3,
            "z": 4,

            "elements": [
                "modularmachinery:blockcasing@4"
            ]
        },
        {
            "x": -1,
            "y": -1,
            "z": 2,
                       "elements": [
                "botania:cellblock@0"
            ]
        },
        {
            "x": 0,
            "y": 1,
            "z": 3,
            "elements": [
                "bloodarsenal:refined_life_essence@0"
            ]
        },
        {
            "x": 1,
            "y": 3,
            "z": 4,

            "elements": [
                "modularmachinery:blockcasing@4"
            ]
        },
        {
            "x": 0,
            "y": -1,
            "z": 2,
                       "elements": [
                "botania:cellblock@0"
            ]
        },
        {
            "x": 1,
            "y": 1,
            "z": 3,
                       "elements": [
                "botania:cellblock@0"
            ]
        },
        {
            "x": 2,
            "y": 3,
            "z": 4,

            "elements": [
                "modularmachinery:blockcasing@4"
            ]
        },
        {
            "x": 1,
            "y": -1,
            "z": 2,
                       "elements": [
                "botania:cellblock@0"
            ]
        },
        {
            "x": 3,
            "y": 3,
            "z": 4,

            "elements": [
                "modularmachinery:blockcasing@4"
            ]
        },
        {
            "x": 2,
            "y": -1,
            "z": 2,
                       "elements": [
                "botania:cellblock@0"
            ]
        },
        {
            "x": 4,
            "y": 3,
            "z": 4,
            "elements": [
                "techreborn:fusion_coil@0"
            ]
        },
        {
            "x": 3,
            "y": -1,
            "z": 2,
                       "elements": [
                "botania:cellblock@0"
            ]
        },
        {
            "x": 4,
            "y": 1,
            "z": 3,
            "elements": [
                "actuallyadditions:block_greenhouse_glass@0"
            ]
        },
        {
            "x": 4,
            "y": -1,
            "z": 2,
            "elements": [
                "techreborn:fusion_coil@0"
            ]
        },
        {
            "x": -4,
            "y": 2,
            "z": 3,
            "elements": [
                "actuallyadditions:block_greenhouse_glass@0"
            ]
        },
        {
            "x": -4,
            "y": 0,
            "z": 2,
            "elements": [
                "actuallyadditions:block_greenhouse_glass@0"
            ]
        },
        {
            "x": -3,
            "y": 2,
            "z": 3,
                       "elements": [
                "botania:cellblock@0"
            ]
        },
        {
            "x": -4,
            "y": -2,
            "z": 1,
            "elements": [
                "libvulpes:structuremachine@0"
            ]
        },
        {
            "x": -2,
            "y": 2,
            "z": 3,
                       "elements": [
                "botania:cellblock@0"
            ]
        },
        {
            "x": -3,
            "y": -2,
            "z": 1,
            "elements": [
                "libvulpes:structuremachine@0"
            ]
        },
        {
            "x": -1,
            "y": 2,
            "z": 3,
                       "elements": [
                "botania:cellblock@0"
            ]
        },
        {
            "x": -2,
            "y": -2,
            "z": 1,
            "elements": [
                "libvulpes:structuremachine@0"
            ]
        },
        {
            "x": -1,
            "y": 0,
            "z": 2,
                       "elements": [
                "botania:cellblock@0"
            ]
        },
        {
            "x": 0,
            "y": 2,
            "z": 3,
                       "elements": [
                "botania:cellblock@0"
            ]
        },
        {
            "x": -1,
            "y": -2,
            "z": 1,
            "elements": [
                "libvulpes:structuremachine@0"
            ]
        },
        {
            "x": 0,
            "y": 0,
            "z": 2,
                       "elements": [
                "botania:cellblock@0"
            ]
        },
        {
            "x": 1,
            "y": 2,
            "z": 3,
                       "elements": [
                "botania:cellblock@0"
            ]
        },
        {
            "x": 0,
            "y": -2,
            "z": 1,
            "elements": [
                "libvulpes:structuremachine@0"
            ]
        },
        {
            "x": 1,
            "y": 0,
            "z": 2,
                       "elements": [
                "botania:cellblock@0"
            ]
        },
        {
            "x": 2,
            "y": 2,
            "z": 3,
                       "elements": [
                "botania:cellblock@0"
            ]
        },
        {
            "x": 1,
            "y": -2,
            "z": 1,
            "elements": [
                "libvulpes:structuremachine@0"
            ]
        },
        {
            "x": 3,
            "y": 2,
            "z": 3,
                       "elements": [
                "botania:cellblock@0"
            ]
        },
        {
            "x": 2,
            "y": -2,
            "z": 1,
            "elements": [
                "libvulpes:structuremachine@0"
            ]
        },
        {
            "x": 4,
            "y": 2,
            "z": 3,
            "elements": [
                "actuallyadditions:block_greenhouse_glass@0"
            ]
        },
        {
            "x": 3,
            "y": -2,
            "z": 1,
            "elements": [
                "libvulpes:structuremachine@0"
            ]
        },
        {
            "x": 4,
            "y": 0,
            "z": 2,
            "elements": [
                "actuallyadditions:block_greenhouse_glass@0"
            ]
        },
        {
            "x": 4,
            "y": -2,
            "z": 1,
            "elements": [
                "libvulpes:structuremachine@0"
            ]
        },
        {
            "x": -4,
            "y": 3,
            "z": 3,
            "elements": [
                "techreborn:fusion_coil@0"
            ]
        },
        {
            "x": -4,
            "y": 1,
            "z": 2,
            "elements": [
                "actuallyadditions:block_greenhouse_glass@0"
            ]
        },
        {
            "x": -3,
            "y": 3,
            "z": 3,

            "elements": [
                "modularmachinery:blockcasing@4"
            ]
        },
        {
            "x": -4,
            "y": -1,
            "z": 1,
            "elements": [
                "techreborn:fusion_coil@0"
            ]
        },
        {
            "x": -2,
            "y": 3,
            "z": 3,

            "elements": [
                "modularmachinery:blockcasing@4"
            ]
        },
        {
            "x": -3,
            "y": -1,
            "z": 1,
            "elements": [
                "mysticalagriculture:ingot_storage@5"
            ]
        },
        {
            "x": -1,
            "y": 3,
            "z": 3,

            "elements": [
                "modularmachinery:blockcasing@4"
            ]
        },
        {
            "x": -2,
            "y": -1,
            "z": 1,
                       "elements": [
                "botania:cellblock@0"
            ]
        },
        {
            "x": -1,
            "y": 1,
            "z": 2,
                       "elements": [
                "botania:cellblock@0"
            ]
        },
        {
            "x": 0,
            "y": 3,
            "z": 3,

            "elements": [
                "modularmachinery:blockcasing@4"
            ]
        },
        {
            "x": -1,
            "y": -1,
            "z": 1,
                       "elements": [
                "botania:cellblock@0"
            ]
        },
        {
            "x": 0,
            "y": 1,
            "z": 2,
                       "elements": [
                "botania:cellblock@0"
            ]
        },
        {
            "x": 1,
            "y": 3,
            "z": 3,

            "elements": [
                "modularmachinery:blockcasing@4"
            ]
        },
        {
            "x": 0,
            "y": -1,
            "z": 1,
                       "elements": [
                "botania:cellblock@0"
            ]
        },
        {
            "x": 1,
            "y": 1,
            "z": 2,
                       "elements": [
                "botania:cellblock@0"
            ]
        },
        {
            "x": 2,
            "y": 3,
            "z": 3,

            "elements": [
                "modularmachinery:blockcasing@4"
            ]
        },
        {
            "x": 1,
            "y": -1,
            "z": 1,
                       "elements": [
                "botania:cellblock@0"
            ]
        },
        {
            "x": 3,
            "y": 3,
            "z": 3,

            "elements": [
                "modularmachinery:blockcasing@4"
            ]
        },
        {
            "x": 2,
            "y": -1,
            "z": 1,
                       "elements": [
                "botania:cellblock@0"
            ]
        },
        {
            "x": 4,
            "y": 3,
            "z": 3,
            "elements": [
                "techreborn:fusion_coil@0"
            ]
        },
        {
            "x": 3,
            "y": -1,
            "z": 1,
            "elements": [
                "mysticalagriculture:ingot_storage@5"
            ]
        },
        {
            "x": 4,
            "y": 1,
            "z": 2,
            "elements": [
                "actuallyadditions:block_greenhouse_glass@0"
            ]
        },
        {
            "x": 4,
            "y": -1,
            "z": 1,
            "elements": [
                "techreborn:fusion_coil@0"
            ]
        },
        {
            "x": -4,
            "y": 2,
            "z": 2,
            "elements": [
                "actuallyadditions:block_greenhouse_glass@0"
            ]
        },
        {
            "x": -4,
            "y": 0,
            "z": 1,
            "elements": [
                "actuallyadditions:block_greenhouse_glass@0"
            ]
        },
        {
            "x": -3,
            "y": 2,
            "z": 2,
                       "elements": [
                "botania:cellblock@0"
            ]
        },
        {
            "x": -2,
            "y": 2,
            "z": 2,
                       "elements": [
                "botania:cellblock@0"
            ]
        },
        {
            "x": -1,
            "y": 2,
            "z": 2,
                       "elements": [
                "botania:cellblock@0"
            ]
        },
        {
            "x": 0,
            "y": 2,
            "z": 2,
                       "elements": [
                "botania:cellblock@0"
            ]
        },
        {
            "x": 1,
            "y": 2,
            "z": 2,
                       "elements": [
                "botania:cellblock@0"
            ]
        },
        {
            "x": 2,
            "y": 2,
            "z": 2,
             "elements": [
                "botania:cellblock@0"
            ]
        },
        {
            "x": 3,
            "y": 2,
            "z": 2,
            "elements": [
                "botania:cellblock@0"
            ]
        },
        {
            "x": 4,
            "y": 2,
            "z": 2,
            "elements": [
                "actuallyadditions:block_greenhouse_glass@0"
            ]
        },
        {
            "x": 4,
            "y": 0,
            "z": 1,
            "elements": [
                "actuallyadditions:block_greenhouse_glass@0"
            ]
        },
        {
            "x": -4,
            "y": 3,
            "z": 2,
            "elements": [
                "techreborn:fusion_coil@0"
            ]
        },
        {
            "x": -4,
            "y": 1,
            "z": 1,
            "elements": [
                "actuallyadditions:block_greenhouse_glass@0"
            ]
        },
        {
            "x": -3,
            "y": 3,
            "z": 2,

            "elements": [
                "modularmachinery:blockcasing@4"
            ]
        },
        {
            "x": -2,
            "y": 3,
            "z": 2,

            "elements": [
                "modularmachinery:blockcasing@4"
            ]
        },
        {
            "x": -1,
            "y": 3,
            "z": 2,

            "elements": [
                "modularmachinery:blockcasing@4"
            ]
        },
        {
            "x": 0,
            "y": 3,
            "z": 2,

            "elements": [
                "modularmachinery:blockcasing@4"
            ]
        },
        {
            "x": 1,
            "y": 3,
            "z": 2,

            "elements": [
                "modularmachinery:blockcasing@4"
            ]
        },
        {
            "x": 2,
            "y": 3,
            "z": 2,

            "elements": [
                "modularmachinery:blockcasing@4"
            ]
        },
        {
            "x": 3,
            "y": 3,
            "z": 2,

            "elements": [
                "modularmachinery:blockcasing@4"
            ]
        },
        {
            "x": 4,
            "y": 3,
            "z": 2,
            "elements": [
                "techreborn:fusion_coil@0"
            ]
        },
        {
            "x": 4,
            "y": 1,
            "z": 1,
            "elements": [
                "actuallyadditions:block_greenhouse_glass@0"
            ]
        },
        {
            "x": -4,
            "y": 2,
            "z": 1,
            "elements": [
                "actuallyadditions:block_greenhouse_glass@0"
            ]
        },
        {
            "x": -3,
            "y": 2,
            "z": 1,
                       "elements": [
                "botania:cellblock@0"
            ]
        },
        {
            "x": -2,
            "y": 2,
            "z": 1,
                       "elements": [
                "botania:cellblock@0"
            ]
        },
        {
            "x": -1,
            "y": 2,
            "z": 1,
                       "elements": [
                "botania:cellblock@0"
            ]
        },
        {
            "x": 0,
            "y": 2,
            "z": 1,
                       "elements": [
                "botania:cellblock@0"
            ]
        }
    ]}