{
    "registryname": "ebf", 
    "localizedname": "ia.machine.ebf.name", 
    "requires-blueprint": false, 
    "color": "828889", 
    "parts": [
        {
            "x": -1,
            "y": 0,
            "z": 2,
            "elements": [
                "thermalfoundation:storage_alloy@2"
            ]
        },
        {
            "x": -1,
            "y": 0,
            "z": 1,
            "elements": [
                "thermalfoundation:storage_alloy@2"
            ]
        },
        {
            "x": 1,
            "y": 0,
            "z": 2,
            "elements": [
                "thermalfoundation:storage_alloy@2"
            ]
        },
        {
            "x": -1,
            "y": 0,
            "z": 0,
            "elements": [
                "thermalfoundation:storage_alloy@2"
            ]
        },
        {
            "x": 1,
            "y": 0,
            "z": 1,
            "elements": [
                "thermalfoundation:storage_alloy@2"
            ]
        },
        {
            "x": 0,
            "y": 3,
            "z": 1,
            "elements": [
                "modularmachinery:blockenergyinputhatch",
                "thermalfoundation:storage_alloy@2"
            ]
        },
        {
            "x": 0,
            "y": 3,
            "z": 0,
            "elements": [
                "modularmachinery:blockstarlightproviderinput",
                "thermalfoundation:storage_alloy@2"
            ]
        },
        {
            "x": 1,
            "y": 0,
            "z": 0,
            "elements": [
                "thermalfoundation:storage_alloy@2"
            ]
        },
        {
            "x": 0,
            "y": 3,
            "z": 2,
            "elements": [
                "modularmachinery:blockparallelcontroller",
                "thermalfoundation:storage_alloy@2"
            ]
        },
        {
            "x": 1,
            "y": 1,
            "z": 0,
            "elements": [
                "contenttweaker:sub_block_holder_1@0",
                "contenttweaker:sub_block_holder_1@6",
                "contenttweaker:sub_block_holder_0@6"
            ]
        },
        {
            "x": 1,
            "y": 1,
            "z": 2,
            "elements": [
                "contenttweaker:sub_block_holder_1@0",
                "contenttweaker:sub_block_holder_1@6",
                "contenttweaker:sub_block_holder_0@6"
            ]
        },
        {
            "x": 1,
            "y": 1,
            "z": 1,
            "elements": [
                "contenttweaker:sub_block_holder_1@0",
                "contenttweaker:sub_block_holder_1@6",
                "contenttweaker:sub_block_holder_0@6"
            ]
        },
        {
            "x": -1,
            "y": 1,
            "z": 2,
            "elements": [
                "contenttweaker:sub_block_holder_1@0",
                "contenttweaker:sub_block_holder_1@6",
                "contenttweaker:sub_block_holder_0@6"
            ]
        },
        {
            "x": -1,
            "y": 1,
            "z": 1,
            "elements": [
                "contenttweaker:sub_block_holder_1@0",
                "contenttweaker:sub_block_holder_1@6",
                "contenttweaker:sub_block_holder_0@6"
            ]
        },
        {
            "x": -1,
            "y": 1,
            "z": 0,
            "elements": [
                "contenttweaker:sub_block_holder_1@0",
                "contenttweaker:sub_block_holder_1@6",
                "contenttweaker:sub_block_holder_0@6"
            ]
        },
        {
            "x": 0,
            "y": 2,
            "z": 2,
            "elements": [
                "contenttweaker:sub_block_holder_1@0",
                "contenttweaker:sub_block_holder_1@6",
                "contenttweaker:sub_block_holder_0@6"
            ]
        },
        {
            "x": 0,
            "y": 2,
            "z": 0,
            "elements": [
                "contenttweaker:sub_block_holder_1@0",
                "contenttweaker:sub_block_holder_1@6",
                "contenttweaker:sub_block_holder_0@6"
            ]
        },
        {
            "x": 1,
            "y": 3,
            "z": 1,
            "elements": [
                "modularmachinery:blockmanaproviderinput",
                "thermalfoundation:storage_alloy@2"
            ]
        },
        {
            "x": 1,
            "y": 3,
            "z": 2,
            "elements": [
                "modularmachinery:blockfluidoutputhatch",
                "modularmachinery:blockmefluidoutputbus",
                "thermalfoundation:storage_alloy@2"
            ]
        },
        {
            "x": 0,
            "y": 0,
            "z": 2,
            "elements": [
                "thermalfoundation:storage_alloy@2"
            ]
        },
        {
            "x": 0,
            "y": 0,
            "z": 1,
            "elements": [
                "thermalfoundation:storage_alloy@2"
            ]
        },
        {
            "x": 1,
            "y": 3,
            "z": 0,
            "elements": [
                "modularmachinery:blockoutputbus",
                "modularmachinery:blockmeitemoutputbus",
                "thermalfoundation:storage_alloy@2"
            ]
        },
        {
            "x": -1,
            "y": 2,
            "z": 1,
            "elements": [
                "contenttweaker:sub_block_holder_1@0",
                "contenttweaker:sub_block_holder_1@6",
                "contenttweaker:sub_block_holder_0@6"
            ]
        },
        {
            "x": -1,
            "y": 2,
            "z": 0,
            "elements": [
                "contenttweaker:sub_block_holder_1@0",
                "contenttweaker:sub_block_holder_1@6",
                "contenttweaker:sub_block_holder_0@6"
            ]
        },
        {
            "x": 1,
            "y": 2,
            "z": 2,
            "elements": [
                "contenttweaker:sub_block_holder_1@0",
                "contenttweaker:sub_block_holder_1@6",
                "contenttweaker:sub_block_holder_0@6"
            ]
        },
        {
            "x": -1,
            "y": 3,
            "z": 2,
            "elements": [
                "modularmachinery:blockfluidinputhatch",
                "modularmachinery:blockmefluidinputbus",
                "modularmachinery:blockmepatternprovider",
                "thermalfoundation:storage_alloy@2"
            ]
        },
        {
            "x": 1,
            "y": 2,
            "z": 1,
            "elements": [
                "contenttweaker:sub_block_holder_1@0",
                "contenttweaker:sub_block_holder_1@6",
                "contenttweaker:sub_block_holder_0@6"
            ]
        },
        {
            "x": 1,
            "y": 2,
            "z": 0,
            "elements": [
                "contenttweaker:sub_block_holder_1@0",
                "contenttweaker:sub_block_holder_1@6",
                "contenttweaker:sub_block_holder_0@6"
            ]
        },
        {
            "x": -1,
            "y": 3,
            "z": 1,
            "elements": [
                "modularmachinery:blockgridproviderinput",
                "thermalfoundation:storage_alloy@2"
            ]
        },
        {
            "x": -1,
            "y": 3,
            "z": 0,
            "elements": [
                "modularmachinery:blockinputbus",
                "modularmachinery:blockmeiteminputbus",
                "modularmachinery:blockmepatternprovider",
                "thermalfoundation:storage_alloy@2"
            ]
        },
        {
            "x": -1,
            "y": 2,
            "z": 2,
            "elements": [
                "contenttweaker:sub_block_holder_1@0",
                "contenttweaker:sub_block_holder_1@6",
                "contenttweaker:sub_block_holder_0@6"
            ]
        },
        {
            "x": 0,
            "y": 1,
            "z": 0,
            "elements": [
                "contenttweaker:sub_block_holder_1@0",
                "contenttweaker:sub_block_holder_1@6",
                "contenttweaker:sub_block_holder_0@6"
            ]
        },
        {
            "x": 0,
            "y": 1,
            "z": 2,
            "elements": [
                "contenttweaker:sub_block_holder_1@0",
                "contenttweaker:sub_block_holder_1@6",
                "contenttweaker:sub_block_holder_0@6"
            ]
        }
    ]}