{
    "registryname": "lightning_infuser", 
    "localizedname": "ia.machine.lightning_infuser.name", 
    "requires-blueprint": false, 
    "color": "000000", 
    "parts": [
        {
            "x": 5,
            "y": 0,
            "z": 9,
            "elements": [
                "qmd:containment_glass@0"
            ]
        },
        {
            "x": 5,
            "y": 0,
            "z": 6,
            "elements": [
                "lightningcraft:metal_block@1"
            ]
        },
        {
            "x": 5,
            "y": 0,
            "z": 2,
            "elements": [
                "qmd:containment_glass@0"
            ]
        },
        {
            "x": 5,
            "y": 0,
            "z": 3,
            "elements": [
                "qmd:containment_glass@0"
            ]
        },
        {
            "x": -2,
            "y": -2,
            "z": 5,
            "elements": [
                "lightningcraft:stone_block@0"
            ]
        },
        {
            "x": -1,
            "y": -1,
            "z": 9,
            "elements": [
                "lightningcraft:stone_block@0"
            ]
        },
        {
            "x": -2,
            "y": -2,
            "z": 6,
            "elements": [
                "lightningcraft:stone_block@0"
            ]
        },
        {
            "x": -2,
            "y": -2,
            "z": 7,
            "elements": [
                "lightningcraft:stone_block@0"
            ]
        },
        {
            "x": -1,
            "y": -1,
            "z": 3,
            "elements": [
                "lightningcraft:stone_block@0"
            ]
        },
        {
            "x": -1,
            "y": -1,
            "z": 4,
            "elements": [
                "mekanism:basicblock@4"
            ]
        },
        {
            "x": -1,
            "y": 6,
            "z": 6,
            "elements": [
                "qmd:containment_glass@0"
            ]
        },
        {
            "x": -1,
            "y": -1,
            "z": 8,
            "elements": [
                "mekanism:basicblock@4"
            ]
        },
        {
            "x": 0,
            "y": 0,
            "z": 12,
            "elements": [
                "modularmachinery:blockenergyinputhatch"
            ]
        },
        {
            "x": 0,
            "y": 0,
            "z": 11,
            "elements": [
                "lightningcraft:metal_block@1"
            ]
        },
        {
            "x": 0,
            "y": 0,
            "z": 10,
            "elements": [
                "lightningcraft:metal_block@1"
            ]
        },
        {
            "x": 0,
            "y": 0,
            "z": 9,
            "elements": [
                "lightningcraft:stone_block@0"
            ]
        },
        {
            "x": 4,
            "y": 5,
            "z": 6,
            "elements": [
                "qmd:containment_glass@0"
            ]
        },
        {
            "x": 0,
            "y": 0,
            "z": 3,
            "elements": [
                "lightningcraft:stone_block@0"
            ]
        },
        {
            "x": 1,
            "y": 2,
            "z": 8,
            "elements": [
                "lightningcraft:stone_block@0"
            ]
        },
        {
            "x": 1,
            "y": 2,
            "z": 7,
            "elements": [
                "lightningcraft:stone_block@0"
            ]
        },
        {
            "x": -4,
            "y": -5,
            "z": 6,
            "elements": [
                "qmd:containment_glass@0"
            ]
        },
        {
            "x": 0,
            "y": 0,
            "z": 2,
            "elements": [
                "lightningcraft:metal_block@1"
            ]
        },
        {
            "x": 1,
            "y": 2,
            "z": 5,
            "elements": [
                "lightningcraft:stone_block@0"
            ]
        },
        {
            "x": 1,
            "y": 2,
            "z": 4,
            "elements": [
                "lightningcraft:stone_block@0"
            ]
        },
        {
            "x": -6,
            "y": -1,
            "z": 6,
            "elements": [
                "lightningcraft:metal_block@1"
            ]
        },
        {
            "x": 0,
            "y": 0,
            "z": 1,
            "elements": [
                "lightningcraft:metal_block@1"
            ]
        },
        {
            "x": 5,
            "y": 0,
            "z": 10,
            "elements": [
                "qmd:containment_glass@0"
            ]
        },
        {
            "x": -5,
            "y": 0,
            "z": 3,
            "elements": [
                "qmd:containment_glass@0"
            ]
        },
        {
            "x": 3,
            "y": 5,
            "z": 6,
            "elements": [
                "qmd:containment_glass@0"
            ]
        },
        {
            "x": -5,
            "y": 0,
            "z": 2,
            "elements": [
                "qmd:containment_glass@0"
            ]
        },
        {
            "x": 1,
            "y": 1,
            "z": 4,
            "elements": [
                "mekanism:basicblock@4"
            ]
        },
        {
            "x": 1,
            "y": 1,
            "z": 3,
            "elements": [
                "lightningcraft:stone_block@0"
            ]
        },
        {
            "x": 1,
            "y": 1,
            "z": 8,
            "elements": [
                "mekanism:basicblock@4"
            ]
        },
        {
            "x": 1,
            "y": 1,
            "z": 9,
            "elements": [
                "lightningcraft:stone_block@0"
            ]
        },
        {
            "x": 4,
            "y": 0,
            "z": 1,
            "elements": [
                "qmd:containment_glass@0"
            ]
        },
        {
            "x": 4,
            "y": 0,
            "z": 2,
            "elements": [
                "qmd:containment_glass@0"
            ]
        },
        {
            "x": -2,
            "y": -1,
            "z": 8,
            "elements": [
                "lightningcraft:stone_block@0"
            ]
        },
        {
            "x": -2,
            "y": -1,
            "z": 7,
            "elements": [
                "mekanism:basicblock@4"
            ]
        },
        {
            "x": -2,
            "y": -1,
            "z": 4,
            "elements": [
                "lightningcraft:stone_block@0"
            ]
        },
        {
            "x": -2,
            "y": -1,
            "z": 5,
            "elements": [
                "mekanism:basicblock@4"
            ]
        },
        {
            "x": 6,
            "y": 1,
            "z": 6,
            "elements": [
                "lightningcraft:metal_block@1"
            ]
        },
        {
            "x": -4,
            "y": -4,
            "z": 6,
            "elements": [
                "qmd:containment_glass@0"
            ]
        },
        {
            "x": 0,
            "y": -6,
            "z": 3,
            "elements": [
                "qmd:containment_glass@0"
            ]
        },
        {
            "x": 0,
            "y": -6,
            "z": 4,
            "elements": [
                "qmd:containment_glass@0"
            ]
        },
        {
            "x": -5,
            "y": 0,
            "z": 9,
            "elements": [
                "qmd:containment_glass@0"
            ]
        },
        {
            "x": -1,
            "y": -2,
            "z": 7,
            "elements": [
                "lightningcraft:stone_block@0"
            ]
        },
        {
            "x": -1,
            "y": -2,
            "z": 8,
            "elements": [
                "lightningcraft:stone_block@0"
            ]
        },
        {
            "x": 0,
            "y": -6,
            "z": 9,
            "elements": [
                "qmd:containment_glass@0"
            ]
        },
        {
            "x": -5,
            "y": 0,
            "z": 10,
            "elements": [
                "qmd:containment_glass@0"
            ]
        },
        {
            "x": 0,
            "y": -6,
            "z": 7,
            "elements": [
                "qmd:containment_glass@0"
            ]
        },
        {
            "x": 0,
            "y": -6,
            "z": 8,
            "elements": [
                "qmd:containment_glass@0"
            ]
        },
        {
            "x": 0,
            "y": -6,
            "z": 5,
            "elements": [
                "qmd:containment_glass@0"
            ]
        },
        {
            "x": -1,
            "y": -2,
            "z": 4,
            "elements": [
                "lightningcraft:stone_block@0"
            ]
        },
        {
            "x": -5,
            "y": 0,
            "z": 6,
            "elements": [
                "lightningcraft:metal_block@1"
            ]
        },
        {
            "x": 0,
            "y": -6,
            "z": 6,
            "elements": [
                "modularmachinery:blockaspectproviderinput"
            ]
        },
        {
            "x": -1,
            "y": -2,
            "z": 5,
            "elements": [
                "lightningcraft:stone_block@0"
            ]
        },
        {
            "x": 1,
            "y": 0,
            "z": 3,
            "elements": [
                "lightningcraft:stone_block@0"
            ]
        },
        {
            "x": -3,
            "y": -5,
            "z": 6,
            "elements": [
                "qmd:containment_glass@0"
            ]
        },
        {
            "x": 1,
            "y": 0,
            "z": 0,
            "elements": [
                "lightningcraft:metal_block@1"
            ]
        },
        {
            "x": 1,
            "y": 0,
            "z": 12,
            "elements": [
                "lightningcraft:metal_block@1"
            ]
        },
        {
            "x": 3,
            "y": -1,
            "z": 7,
            "elements": [
                "lightningcraft:stone_block@0"
            ]
        },
        {
            "x": 1,
            "y": 0,
            "z": 9,
            "elements": [
                "lightningcraft:stone_block@0"
            ]
        },
        {
            "x": 3,
            "y": -1,
            "z": 5,
            "elements": [
                "lightningcraft:stone_block@0"
            ]
        },
        {
            "x": 3,
            "y": -1,
            "z": 6,
            "elements": [
                "lightningcraft:stone_block@0"
            ]
        },
        {
            "x": -2,
            "y": 6,
            "z": 6,
            "elements": [
                "qmd:containment_glass@0"
            ]
        },
        {
            "x": -5,
            "y": -4,
            "z": 6,
            "elements": [
                "qmd:containment_glass@0"
            ]
        },
        {
            "x": 1,
            "y": 3,
            "z": 5,
            "elements": [
                "lightningcraft:stone_block@0"
            ]
        },
        {
            "x": 1,
            "y": 3,
            "z": 6,
            "elements": [
                "lightningcraft:stone_block@0"
            ]
        },
        {
            "x": -4,
            "y": 4,
            "z": 6,
            "elements": [
                "qmd:containment_glass@0"
            ]
        },
        {
            "x": 1,
            "y": 3,
            "z": 7,
            "elements": [
                "lightningcraft:stone_block@0"
            ]
        },
        {
            "x": 0,
            "y": -5,
            "z": 6,
            "elements": [
                "environmentaltech:lightning_rod_insulated@0"
            ]
        },
        {
            "x": -2,
            "y": 0,
            "z": 4,
            "elements": [
                "lightningcraft:stone_block@0"
            ]
        },
        {
            "x": 4,
            "y": 0,
            "z": 10,
            "elements": [
                "qmd:containment_glass@0"
            ]
        },
        {
            "x": 0,
            "y": -5,
            "z": 10,
            "elements": [
                "qmd:containment_glass@0"
            ]
        },
        {
            "x": -2,
            "y": 0,
            "z": 8,
            "elements": [
                "lightningcraft:stone_block@0"
            ]
        },
        {
            "x": 4,
            "y": 0,
            "z": 6,
            "elements": [
                "lightningcraft:metal_block@1"
            ]
        },
        {
            "x": 0,
            "y": -5,
            "z": 9,
            "elements": [
                "qmd:containment_glass@0"
            ]
        },
        {
            "x": 4,
            "y": 0,
            "z": 11,
            "elements": [
                "qmd:containment_glass@0"
            ]
        },
        {
            "x": -2,
            "y": 0,
            "z": 0,
            "elements": [
                "qmd:containment_glass@0"
            ]
        },
        {
            "x": -3,
            "y": 1,
            "z": 5,
            "elements": [
                "lightningcraft:stone_block@0"
            ]
        },
        {
            "x": 1,
            "y": 6,
            "z": 6,
            "elements": [
                "qmd:containment_glass@0"
            ]
        },
        {
            "x": -3,
            "y": 1,
            "z": 6,
            "elements": [
                "lightningcraft:stone_block@0"
            ]
        },
        {
            "x": -3,
            "y": 1,
            "z": 7,
            "elements": [
                "lightningcraft:stone_block@0"
            ]
        },
        {
            "x": 4,
            "y": 4,
            "z": 6,
            "elements": [
                "qmd:containment_glass@0"
            ]
        },
        {
            "x": -2,
            "y": 0,
            "z": 12,
            "elements": [
                "qmd:containment_glass@0"
            ]
        },
        {
            "x": -6,
            "y": -3,
            "z": 6,
            "elements": [
                "qmd:containment_glass@0"
            ]
        },
        {
            "x": 0,
            "y": -2,
            "z": 0,
            "elements": [
                "qmd:containment_glass@0"
            ]
        },
        {
            "x": 3,
            "y": -5,
            "z": 6,
            "elements": [
                "qmd:containment_glass@0"
            ]
        },
        {
            "x": 6,
            "y": 2,
            "z": 6,
            "elements": [
                "qmd:containment_glass@0"
            ]
        },
        {
            "x": 0,
            "y": -2,
            "z": 8,
            "elements": [
                "lightningcraft:stone_block@0"
            ]
        },
        {
            "x": 2,
            "y": 2,
            "z": 5,
            "elements": [
                "lightningcraft:stone_block@0"
            ]
        },
        {
            "x": 2,
            "y": 2,
            "z": 6,
            "elements": [
                "lightningcraft:stone_block@0"
            ]
        },
        {
            "x": 2,
            "y": 2,
            "z": 7,
            "elements": [
                "lightningcraft:stone_block@0"
            ]
        },
        {
            "x": 0,
            "y": -2,
            "z": 4,
            "elements": [
                "lightningcraft:stone_block@0"
            ]
        },
        {
            "x": 2,
            "y": -1,
            "z": 5,
            "elements": [
                "mekanism:basicblock@4"
            ]
        },
        {
            "x": 1,
            "y": -6,
            "z": 6,
            "elements": [
                "qmd:containment_glass@0"
            ]
        },
        {
            "x": 2,
            "y": -1,
            "z": 4,
            "elements": [
                "lightningcraft:stone_block@0"
            ]
        },
        {
            "x": 0,
            "y": -2,
            "z": 12,
            "elements": [
                "qmd:containment_glass@0"
            ]
        },
        {
            "x": 6,
            "y": -1,
            "z": 6,
            "elements": [
                "lightningcraft:metal_block@1"
            ]
        },
        {
            "x": 2,
            "y": -1,
            "z": 7,
            "elements": [
                "mekanism:basicblock@4"
            ]
        },
        {
            "x": 0,
            "y": -5,
            "z": 2,
            "elements": [
                "qmd:containment_glass@0"
            ]
        },
        {
            "x": 0,
            "y": -5,
            "z": 3,
            "elements": [
                "qmd:containment_glass@0"
            ]
        },
        {
            "x": 2,
            "y": -1,
            "z": 8,
            "elements": [
                "lightningcraft:stone_block@0"
            ]
        },
        {
            "x": -1,
            "y": 2,
            "z": 8,
            "elements": [
                "lightningcraft:stone_block@0"
            ]
        },
        {
            "x": -1,
            "y": 2,
            "z": 7,
            "elements": [
                "lightningcraft:stone_block@0"
            ]
        },
        {
            "x": -6,
            "y": 0,
            "z": 4,
            "elements": [
                "qmd:containment_glass@0"
            ]
        },
        {
            "x": -6,
            "y": 0,
            "z": 3,
            "elements": [
                "qmd:containment_glass@0"
            ]
        },
        {
            "x": 0,
            "y": 4,
            "z": 11,
            "elements": [
                "qmd:containment_glass@0"
            ]
        },
        {
            "x": -6,
            "y": 0,
            "z": 8,
            "elements": [
                "qmd:containment_glass@0"
            ]
        },
        {
            "x": -6,
            "y": 0,
            "z": 7,
            "elements": [
                "lightningcraft:metal_block@1"
            ]
        },
        {
            "x": -6,
            "y": 0,
            "z": 6,
            "elements": [
                "modularmachinery:blockinputbus",
                "modularmachinery:blockmepatternprovider"
            ]
        },
        {
            "x": 0,
            "y": 4,
            "z": 10,
            "elements": [
                "qmd:containment_glass@0"
            ]
        },
        {
            "x": -6,
            "y": 0,
            "z": 5,
            "elements": [
                "lightningcraft:metal_block@1"
            ]
        },
        {
            "x": -1,
            "y": 2,
            "z": 5,
            "elements": [
                "lightningcraft:stone_block@0"
            ]
        },
        {
            "x": -1,
            "y": 2,
            "z": 4,
            "elements": [
                "lightningcraft:stone_block@0"
            ]
        },
        {
            "x": 0,
            "y": 4,
            "z": 6,
            "elements": [
                "environmentaltech:lightning_rod_insulated@0"
            ]
        },
        {
            "x": -6,
            "y": 0,
            "z": 9,
            "elements": [
                "qmd:containment_glass@0"
            ]
        },
        {
            "x": 0,
            "y": 1,
            "z": 9,
            "elements": [
                "lightningcraft:stone_block@0"
            ]
        },
        {
            "x": 0,
            "y": 1,
            "z": 12,
            "elements": [
                "lightningcraft:metal_block@1"
            ]
        },
        {
            "x": 0,
            "y": 1,
            "z": 0,
            "elements": [
                "lightningcraft:metal_block@1"
            ]
        },
        {
            "x": 0,
            "y": 1,
            "z": 3,
            "elements": [
                "lightningcraft:stone_block@0"
            ]
        },
        {
            "x": 1,
            "y": -3,
            "z": 7,
            "elements": [
                "lightningcraft:stone_block@0"
            ]
        },
        {
            "x": 1,
            "y": -3,
            "z": 6,
            "elements": [
                "lightningcraft:stone_block@0"
            ]
        },
        {
            "x": 1,
            "y": -3,
            "z": 5,
            "elements": [
                "lightningcraft:stone_block@0"
            ]
        },
        {
            "x": 0,
            "y": -3,
            "z": 12,
            "elements": [
                "qmd:containment_glass@0"
            ]
        },
        {
            "x": -3,
            "y": 0,
            "z": 5,
            "elements": [
                "lightningcraft:stone_block@0"
            ]
        },
        {
            "x": 6,
            "y": -2,
            "z": 6,
            "elements": [
                "qmd:containment_glass@0"
            ]
        },
        {
            "x": 0,
            "y": -3,
            "z": 11,
            "elements": [
                "qmd:containment_glass@0"
            ]
        },
        {
            "x": -3,
            "y": 0,
            "z": 6,
            "elements": [
                "lightningcraft:stone_block@0"
            ]
        },
        {
            "x": -3,
            "y": 0,
            "z": 7,
            "elements": [
                "lightningcraft:stone_block@0"
            ]
        },
        {
            "x": -3,
            "y": 0,
            "z": 11,
            "elements": [
                "qmd:containment_glass@0"
            ]
        },
        {
            "x": 0,
            "y": -3,
            "z": 5,
            "elements": [
                "lightningcraft:stone_block@0"
            ]
        },
        {
            "x": -3,
            "y": 0,
            "z": 12,
            "elements": [
                "qmd:containment_glass@0"
            ]
        },
        {
            "x": -5,
            "y": 4,
            "z": 6,
            "elements": [
                "qmd:containment_glass@0"
            ]
        },
        {
            "x": 0,
            "y": -3,
            "z": 6,
            "elements": [
                "lightningcraft:stone_block@0"
            ]
        },
        {
            "x": 0,
            "y": -3,
            "z": 7,
            "elements": [
                "lightningcraft:stone_block@0"
            ]
        },
        {
            "x": -2,
            "y": 1,
            "z": 7,
            "elements": [
                "mekanism:basicblock@4"
            ]
        },
        {
            "x": -2,
            "y": 1,
            "z": 4,
            "elements": [
                "lightningcraft:stone_block@0"
            ]
        },
        {
            "x": -6,
            "y": 3,
            "z": 6,
            "elements": [
                "qmd:containment_glass@0"
            ]
        },
        {
            "x": 0,
            "y": 4,
            "z": 1,
            "elements": [
                "qmd:containment_glass@0"
            ]
        },
        {
            "x": -2,
            "y": 1,
            "z": 5,
            "elements": [
                "mekanism:basicblock@4"
            ]
        },
        {
            "x": 0,
            "y": 4,
            "z": 2,
            "elements": [
                "qmd:containment_glass@0"
            ]
        },
        {
            "x": 0,
            "y": -3,
            "z": 0,
            "elements": [
                "qmd:containment_glass@0"
            ]
        },
        {
            "x": 0,
            "y": -3,
            "z": 1,
            "elements": [
                "qmd:containment_glass@0"
            ]
        },
        {
            "x": 1,
            "y": -2,
            "z": 8,
            "elements": [
                "lightningcraft:stone_block@0"
            ]
        },
        {
            "x": 1,
            "y": -2,
            "z": 7,
            "elements": [
                "lightningcraft:stone_block@0"
            ]
        },
        {
            "x": 1,
            "y": -2,
            "z": 5,
            "elements": [
                "lightningcraft:stone_block@0"
            ]
        },
        {
            "x": 1,
            "y": -2,
            "z": 4,
            "elements": [
                "lightningcraft:stone_block@0"
            ]
        },
        {
            "x": -3,
            "y": 0,
            "z": 0,
            "elements": [
                "qmd:containment_glass@0"
            ]
        },
        {
            "x": -2,
            "y": 1,
            "z": 8,
            "elements": [
                "lightningcraft:stone_block@0"
            ]
        },
        {
            "x": 2,
            "y": 6,
            "z": 6,
            "elements": [
                "qmd:containment_glass@0"
            ]
        },
        {
            "x": -3,
            "y": 0,
            "z": 1,
            "elements": [
                "qmd:containment_glass@0"
            ]
        },
        {
            "x": 5,
            "y": 3,
            "z": 6,
            "elements": [
                "qmd:containment_glass@0"
            ]
        },
        {
            "x": -4,
            "y": 5,
            "z": 6,
            "elements": [
                "qmd:containment_glass@0"
            ]
        },
        {
            "x": 5,
            "y": -3,
            "z": 6,
            "elements": [
                "qmd:containment_glass@0"
            ]
        },
        {
            "x": 3,
            "y": 1,
            "z": 7,
            "elements": [
                "lightningcraft:stone_block@0"
            ]
        },
        {
            "x": 3,
            "y": 1,
            "z": 5,
            "elements": [
                "lightningcraft:stone_block@0"
            ]
        },
        {
            "x": 3,
            "y": 1,
            "z": 6,
            "elements": [
                "lightningcraft:stone_block@0"
            ]
        },
        {
            "x": -1,
            "y": 3,
            "z": 7,
            "elements": [
                "lightningcraft:stone_block@0"
            ]
        },
        {
            "x": -1,
            "y": 3,
            "z": 6,
            "elements": [
                "lightningcraft:stone_block@0"
            ]
        },
        {
            "x": 1,
            "y": -1,
            "z": 4,
            "elements": [
                "mekanism:basicblock@4"
            ]
        },
        {
            "x": 3,
            "y": -6,
            "z": 6,
            "elements": [
                "qmd:containment_glass@0"
            ]
        },
        {
            "x": -3,
            "y": -6,
            "z": 6,
            "elements": [
                "qmd:containment_glass@0"
            ]
        },
        {
            "x": -1,
            "y": 3,
            "z": 5,
            "elements": [
                "lightningcraft:stone_block@0"
            ]
        },
        {
            "x": 1,
            "y": -1,
            "z": 3,
            "elements": [
                "lightningcraft:stone_block@0"
            ]
        },
        {
            "x": -2,
            "y": 2,
            "z": 7,
            "elements": [
                "lightningcraft:stone_block@0"
            ]
        },
        {
            "x": 0,
            "y": 3,
            "z": 1,
            "elements": [
                "qmd:containment_glass@0"
            ]
        },
        {
            "x": 0,
            "y": 3,
            "z": 0,
            "elements": [
                "qmd:containment_glass@0"
            ]
        },
        {
            "x": 0,
            "y": 3,
            "z": 5,
            "elements": [
                "lightningcraft:stone_block@0"
            ]
        },
        {
            "x": 1,
            "y": -1,
            "z": 9,
            "elements": [
                "lightningcraft:stone_block@0"
            ]
        },
        {
            "x": 1,
            "y": -1,
            "z": 8,
            "elements": [
                "mekanism:basicblock@4"
            ]
        },
        {
            "x": 0,
            "y": 3,
            "z": 7,
            "elements": [
                "lightningcraft:stone_block@0"
            ]
        },
        {
            "x": 0,
            "y": 3,
            "z": 6,
            "elements": [
                "lightningcraft:stone_block@0"
            ]
        },
        {
            "x": 0,
            "y": 3,
            "z": 11,
            "elements": [
                "qmd:containment_glass@0"
            ]
        },
        {
            "x": 0,
            "y": 3,
            "z": 12,
            "elements": [
                "qmd:containment_glass@0"
            ]
        },
        {
            "x": 2,
            "y": -6,
            "z": 6,
            "elements": [
                "qmd:containment_glass@0"
            ]
        },
        {
            "x": -2,
            "y": -6,
            "z": 6,
            "elements": [
                "qmd:containment_glass@0"
            ]
        },
        {
            "x": 5,
            "y": -4,
            "z": 6,
            "elements": [
                "qmd:containment_glass@0"
            ]
        },
        {
            "x": 0,
            "y": 5,
            "z": 2,
            "elements": [
                "qmd:containment_glass@0"
            ]
        },
        {
            "x": 0,
            "y": 5,
            "z": 3,
            "elements": [
                "qmd:containment_glass@0"
            ]
        },
        {
            "x": 2,
            "y": 0,
            "z": 8,
            "elements": [
                "lightningcraft:stone_block@0"
            ]
        },
        {
            "x": 0,
            "y": 5,
            "z": 6,
            "elements": [
                "environmentaltech:lightning_rod_insulated@0"
            ]
        },
        {
            "x": 2,
            "y": 0,
            "z": 12,
            "elements": [
                "qmd:containment_glass@0"
            ]
        },
        {
            "x": 0,
            "y": 5,
            "z": 9,
            "elements": [
                "qmd:containment_glass@0"
            ]
        },
        {
            "x": -5,
            "y": 3,
            "z": 6,
            "elements": [
                "qmd:containment_glass@0"
            ]
        },
        {
            "x": -1,
            "y": 1,
            "z": 9,
            "elements": [
                "lightningcraft:stone_block@0"
            ]
        },
        {
            "x": -5,
            "y": -3,
            "z": 6,
            "elements": [
                "qmd:containment_glass@0"
            ]
        },
        {
            "x": -1,
            "y": 1,
            "z": 8,
            "elements": [
                "mekanism:basicblock@4"
            ]
        },
        {
            "x": 4,
            "y": -5,
            "z": 6,
            "elements": [
                "qmd:containment_glass@0"
            ]
        },
        {
            "x": 2,
            "y": 0,
            "z": 0,
            "elements": [
                "qmd:containment_glass@0"
            ]
        },
        {
            "x": -3,
            "y": 6,
            "z": 6,
            "elements": [
                "qmd:containment_glass@0"
            ]
        },
        {
            "x": -2,
            "y": 2,
            "z": 6,
            "elements": [
                "lightningcraft:stone_block@0"
            ]
        },
        {
            "x": 2,
            "y": 0,
            "z": 4,
            "elements": [
                "lightningcraft:stone_block@0"
            ]
        },
        {
            "x": -2,
            "y": 2,
            "z": 5,
            "elements": [
                "lightningcraft:stone_block@0"
            ]
        },
        {
            "x": 0,
            "y": 2,
            "z": 12,
            "elements": [
                "qmd:containment_glass@0"
            ]
        },
        {
            "x": 0,
            "y": 2,
            "z": 8,
            "elements": [
                "lightningcraft:stone_block@0"
            ]
        },
        {
            "x": 2,
            "y": -2,
            "z": 6,
            "elements": [
                "lightningcraft:stone_block@0"
            ]
        },
        {
            "x": 2,
            "y": -2,
            "z": 5,
            "elements": [
                "lightningcraft:stone_block@0"
            ]
        },
        {
            "x": -1,
            "y": -6,
            "z": 6,
            "elements": [
                "qmd:containment_glass@0"
            ]
        },
        {
            "x": -6,
            "y": 1,
            "z": 6,
            "elements": [
                "lightningcraft:metal_block@1"
            ]
        },
        {
            "x": 2,
            "y": 1,
            "z": 8,
            "elements": [
                "lightningcraft:stone_block@0"
            ]
        },
        {
            "x": -1,
            "y": 1,
            "z": 4,
            "elements": [
                "mekanism:basicblock@4"
            ]
        },
        {
            "x": -1,
            "y": 1,
            "z": 3,
            "elements": [
                "lightningcraft:stone_block@0"
            ]
        },
        {
            "x": 2,
            "y": 1,
            "z": 4,
            "elements": [
                "lightningcraft:stone_block@0"
            ]
        },
        {
            "x": 2,
            "y": 1,
            "z": 5,
            "elements": [
                "mekanism:basicblock@4"
            ]
        },
        {
            "x": -4,
            "y": 0,
            "z": 11,
            "elements": [
                "qmd:containment_glass@0"
            ]
        },
        {
            "x": 2,
            "y": 1,
            "z": 7,
            "elements": [
                "mekanism:basicblock@4"
            ]
        },
        {
            "x": 0,
            "y": 5,
            "z": 10,
            "elements": [
                "qmd:containment_glass@0"
            ]
        },
        {
            "x": 0,
            "y": 2,
            "z": 4,
            "elements": [
                "lightningcraft:stone_block@0"
            ]
        },
        {
            "x": -3,
            "y": 5,
            "z": 6,
            "elements": [
                "qmd:containment_glass@0"
            ]
        },
        {
            "x": -6,
            "y": -2,
            "z": 6,
            "elements": [
                "qmd:containment_glass@0"
            ]
        },
        {
            "x": 0,
            "y": 2,
            "z": 0,
            "elements": [
                "qmd:containment_glass@0"
            ]
        },
        {
            "x": 6,
            "y": 0,
            "z": 8,
            "elements": [
                "qmd:containment_glass@0"
            ]
        },
        {
            "x": 6,
            "y": 0,
            "z": 7,
            "elements": [
                "lightningcraft:metal_block@1"
            ]
        },
        {
            "x": 6,
            "y": 0,
            "z": 6,
            "elements": [
                "modularmachinery:blockoutputbus"
            ]
        },
        {
            "x": 6,
            "y": 0,
            "z": 5,
            "elements": [
                "lightningcraft:metal_block@1"
            ]
        },
        {
            "x": 6,
            "y": 0,
            "z": 4,
            "elements": [
                "qmd:containment_glass@0"
            ]
        },
        {
            "x": 6,
            "y": 0,
            "z": 3,
            "elements": [
                "qmd:containment_glass@0"
            ]
        },
        {
            "x": 6,
            "y": 0,
            "z": 9,
            "elements": [
                "qmd:containment_glass@0"
            ]
        },
        {
            "x": 0,
            "y": 6,
            "z": 5,
            "elements": [
                "qmd:containment_glass@0"
            ]
        },
        {
            "x": 0,
            "y": 6,
            "z": 6,
            "elements": [
                "environmentaltech:lightning_rod_insulated@0"
            ]
        },
        {
            "x": 0,
            "y": -1,
            "z": 0,
            "elements": [
                "lightningcraft:metal_block@1"
            ]
        },
        {
            "x": 0,
            "y": -4,
            "z": 10,
            "elements": [
                "qmd:containment_glass@0"
            ]
        },
        {
            "x": 0,
            "y": 6,
            "z": 7,
            "elements": [
                "qmd:containment_glass@0"
            ]
        },
        {
            "x": 0,
            "y": -1,
            "z": 3,
            "elements": [
                "lightningcraft:stone_block@0"
            ]
        },
        {
            "x": 0,
            "y": 6,
            "z": 8,
            "elements": [
                "qmd:containment_glass@0"
            ]
        },
        {
            "x": 0,
            "y": -4,
            "z": 6,
            "elements": [
                "environmentaltech:lightning_rod_insulated@0"
            ]
        },
        {
            "x": 0,
            "y": 6,
            "z": 3,
            "elements": [
                "qmd:containment_glass@0"
            ]
        },
        {
            "x": 0,
            "y": 6,
            "z": 4,
            "elements": [
                "qmd:containment_glass@0"
            ]
        },
        {
            "x": 0,
            "y": -4,
            "z": 1,
            "elements": [
                "qmd:containment_glass@0"
            ]
        },
        {
            "x": 0,
            "y": -1,
            "z": 9,
            "elements": [
                "lightningcraft:stone_block@0"
            ]
        },
        {
            "x": 0,
            "y": -4,
            "z": 2,
            "elements": [
                "qmd:containment_glass@0"
            ]
        },
        {
            "x": 2,
            "y": -2,
            "z": 7,
            "elements": [
                "lightningcraft:stone_block@0"
            ]
        },
        {
            "x": 6,
            "y": 3,
            "z": 6,
            "elements": [
                "qmd:containment_glass@0"
            ]
        },
        {
            "x": 0,
            "y": 6,
            "z": 9,
            "elements": [
                "qmd:containment_glass@0"
            ]
        },
        {
            "x": 0,
            "y": -1,
            "z": 12,
            "elements": [
                "lightningcraft:metal_block@1"
            ]
        },
        {
            "x": 3,
            "y": 0,
            "z": 6,
            "elements": [
                "lightningcraft:stone_block@0"
            ]
        },
        {
            "x": -1,
            "y": 0,
            "z": 3,
            "elements": [
                "lightningcraft:stone_block@0"
            ]
        },
        {
            "x": -6,
            "y": 2,
            "z": 6,
            "elements": [
                "qmd:containment_glass@0"
            ]
        },
        {
            "x": 3,
            "y": 0,
            "z": 7,
            "elements": [
                "lightningcraft:stone_block@0"
            ]
        },
        {
            "x": -1,
            "y": 0,
            "z": 0,
            "elements": [
                "lightningcraft:metal_block@1"
            ]
        },
        {
            "x": 3,
            "y": 0,
            "z": 5,
            "elements": [
                "lightningcraft:stone_block@0"
            ]
        },
        {
            "x": 3,
            "y": 0,
            "z": 11,
            "elements": [
                "qmd:containment_glass@0"
            ]
        },
        {
            "x": -1,
            "y": 0,
            "z": 9,
            "elements": [
                "lightningcraft:stone_block@0"
            ]
        },
        {
            "x": 5,
            "y": 4,
            "z": 6,
            "elements": [
                "qmd:containment_glass@0"
            ]
        },
        {
            "x": 3,
            "y": 0,
            "z": 0,
            "elements": [
                "qmd:containment_glass@0"
            ]
        },
        {
            "x": 0,
            "y": -4,
            "z": 11,
            "elements": [
                "qmd:containment_glass@0"
            ]
        },
        {
            "x": -1,
            "y": 0,
            "z": 12,
            "elements": [
                "lightningcraft:metal_block@1"
            ]
        },
        {
            "x": 3,
            "y": 0,
            "z": 1,
            "elements": [
                "qmd:containment_glass@0"
            ]
        },
        {
            "x": 3,
            "y": 0,
            "z": 12,
            "elements": [
                "qmd:containment_glass@0"
            ]
        },
        {
            "x": -1,
            "y": -3,
            "z": 5,
            "elements": [
                "lightningcraft:stone_block@0"
            ]
        },
        {
            "x": -1,
            "y": -3,
            "z": 6,
            "elements": [
                "lightningcraft:stone_block@0"
            ]
        },
        {
            "x": -1,
            "y": -3,
            "z": 7,
            "elements": [
                "lightningcraft:stone_block@0"
            ]
        },
        {
            "x": 6,
            "y": -3,
            "z": 6,
            "elements": [
                "qmd:containment_glass@0"
            ]
        },
        {
            "x": -4,
            "y": 0,
            "z": 1,
            "elements": [
                "qmd:containment_glass@0"
            ]
        },
        {
            "x": -4,
            "y": 0,
            "z": 2,
            "elements": [
                "qmd:containment_glass@0"
            ]
        },
        {
            "x": -4,
            "y": 0,
            "z": 10,
            "elements": [
                "qmd:containment_glass@0"
            ]
        },
        {
            "x": 4,
            "y": -4,
            "z": 6,
            "elements": [
                "qmd:containment_glass@0"
            ]
        },
        {
            "x": -4,
            "y": 0,
            "z": 6,
            "elements": [
                "lightningcraft:metal_block@1"
            ]
        },
        {
            "x": 3,
            "y": 6,
            "z": 6,
            "elements": [
                "qmd:containment_glass@0"
            ]
        },
        {
            "x": -3,
            "y": -1,
            "z": 7,
            "elements": [
                "lightningcraft:stone_block@0"
            ]
        },
        {
            "x": -3,
            "y": -1,
            "z": 5,
            "elements": [
                "lightningcraft:stone_block@0"
            ]
        },
        {
            "x": -3,
            "y": -1,
            "z": 6,
            "elements": [
                "lightningcraft:stone_block@0"
            ]
        }
    ]}