{
    "registryname": "mana_zoom", 
    "localizedname": "ia.machine.mana_zoom.name", 
    "requires-blueprint": false, 
    "color": "b19cd9", 
    "parts": [
        {
            "x": -1,
            "y": 0,
            "z": 2,
            "elements": [
                "botania:quartztypemana@0"
            ]
        },
        {
            "x": 1,
            "y": 0,
            "z": 2,
            "elements": [
                "botania:quartztypemana@0"
            ]
        },
        {
            "x": 0,
            "y": 3,
            "z": 1,
            "elements": [
                "botania:bifrostperm@0"
            ]
        },
        {
            "x": 1,
            "y": 0,
            "z": -2,
            "elements": [
                "botania:quartztypered@0"
            ]
        },
        {
            "x": 1,
            "y": 1,
            "z": 2,
            "elements": [
                "botania:bifrostperm@0"
            ]
        },
        {
            "x": -1,
            "y": 1,
            "z": 2,
            "elements": [
                "botania:bifrostperm@0"
            ]
        },
        {
            "x": -2,
            "y": 1,
            "z": 0,
            "elements": [
                "botania:bifrostperm@0"
            ]
        },
        {
            "x": -2,
            "y": 1,
            "z": 1,
            "elements": [
                "botania:bifrostperm@0"
            ]
        },
        {
            "x": 0,
            "y": 2,
            "z": 2,
            "elements": [
                "botania:bifrostperm@0"
            ]
        },
        {
            "x": 2,
            "y": 1,
            "z": 0,
            "elements": [
                "botania:bifrostperm@0"
            ]
        },
        {
            "x": 2,
            "y": 1,
            "z": 1,
            "elements": [
                "botania:bifrostperm@0"
            ]
        },
        {
            "x": 2,
            "y": 1,
            "z": -1,
            "elements": [
                "botania:bifrostperm@0"
            ]
        },
        {
            "x": -2,
            "y": 0,
            "z": 1,
            "elements": [
                "botania:quartztypeelf@0"
            ]
        },
        {
            "x": 1,
            "y": 3,
            "z": 1,
            "elements": [
                "botania:bifrostperm@0"
            ]
        },
        {
            "x": 0,
            "y": 0,
            "z": 2,
            "elements": [
                "modularmachinery:blockinputbus"
            ]
        },
        {
            "x": 1,
            "y": 3,
            "z": 0,
            "elements": [
                "botania:bifrostperm@0"
            ]
        },
        {
            "x": -2,
            "y": 1,
            "z": -1,
            "elements": [
                "botania:bifrostperm@0"
            ]
        },
        {
            "x": 1,
            "y": 2,
            "z": 2,
            "elements": [
                "botania:bifrostperm@0"
            ]
        },
        {
            "x": -1,
            "y": 3,
            "z": 1,
            "elements": [
                "botania:bifrostperm@0"
            ]
        },
        {
            "x": -1,
            "y": 3,
            "z": 0,
            "elements": [
                "botania:bifrostperm@0"
            ]
        },
        {
            "x": -2,
            "y": 0,
            "z": -1,
            "elements": [
                "botania:quartztypeblaze@0"
            ]
        },
        {
            "x": -2,
            "y": 0,
            "z": 0,
            "elements": [
                "botania:quartztypesunny@0"
            ]
        },
        {
            "x": -1,
            "y": 2,
            "z": 2,
            "elements": [
                "botania:bifrostperm@0"
            ]
        },
        {
            "x": 2,
            "y": 2,
            "z": 0,
            "elements": [
                "botania:bifrostperm@0"
            ]
        },
        {
            "x": 2,
            "y": 2,
            "z": 1,
            "elements": [
                "botania:bifrostperm@0"
            ]
        },
        {
            "x": -2,
            "y": 2,
            "z": 0,
            "elements": [
                "botania:bifrostperm@0"
            ]
        },
        {
            "x": 2,
            "y": 0,
            "z": 0,
            "elements": [
                "botania:quartztypesunny@0"
            ]
        },
        {
            "x": 2,
            "y": 0,
            "z": -1,
            "elements": [
                "botania:quartztypeblaze@0"
            ]
        },
        {
            "x": -2,
            "y": 2,
            "z": 1,
            "elements": [
                "botania:bifrostperm@0"
            ]
        },
        {
            "x": 0,
            "y": 1,
            "z": 0,
            "elements": [
                "modularmachinery:blockmanaprovideroutput"
            ]
        },
        {
            "x": 2,
            "y": 0,
            "z": 1,
            "elements": [
                "botania:quartztypeelf@0"
            ]
        },
        {
            "x": 0,
            "y": 1,
            "z": 2,
            "elements": [
                "botania:bifrostperm@0"
            ]
        },
        {
            "x": -1,
            "y": 0,
            "z": -2,
            "elements": [
                "botania:quartztypered@0"
            ]
        }
    ]}